<?xml version="1.0" ?>
<!-- =================================================================================== -->
<!-- |    This document was autogenerated by xacro from naorobot.xacro                 | -->
<!-- |    EDITING THIS FILE BY HAND IS NOT RECOMMENDED                                 | -->
<!-- =================================================================================== -->
<!-- *****************************************************************
 ****** File automatically generated by generate_urdf.py script ******
 ********************************************************************* -->
<robot name="naoH25V40" xmlns:xacro="http://www.ros.org/wiki/xacro">
  <transmission name="HeadYaw_Transmission">
    <type>transmission_interface/SimpleTransmission</type>
    <joint name="HeadYaw">
      <hardwareInterface>PositionJointInterface</hardwareInterface>
      <dynamics damping="0.1" friction="0" />
    </joint>

    <gazebo reference="HeadYaw">
      <implicitSpringDamper>1</implicitSpringDamper>
    </gazebo>

    <actuator name="HeadYaw_Motor">
      <!-- Dummy Values -->
      <hardwareInterface>PositionJointInterface</hardwareInterface>
      <mechanicalReduction>150.27</mechanicalReduction>
    </actuator>
  </transmission>
  <transmission name="HeadPitch_Transmission">
    <type>transmission_interface/SimpleTransmission</type>
    <joint name="HeadPitch">
      <hardwareInterface>PositionJointInterface</hardwareInterface>
      <dynamics damping="0.1" friction="0" />
    </joint>

    <gazebo reference="HeadPitch">
      <implicitSpringDamper>1</implicitSpringDamper>
    </gazebo>

    <actuator name="HeadPitch_Motor">
      <!-- Dummy Values -->
      <hardwareInterface>PositionJointInterface</hardwareInterface>
      <mechanicalReduction>173.22</mechanicalReduction>
    </actuator>
  </transmission>
  <transmission name="LShoulderPitch_Transmission">
    <type>transmission_interface/SimpleTransmission</type>
    <joint name="LShoulderPitch">
      <hardwareInterface>PositionJointInterface</hardwareInterface>
      <dynamics damping="0.1" friction="0" />
    </joint>

    <gazebo reference="LShoulderPitch">
      <implicitSpringDamper>1</implicitSpringDamper>
    </gazebo>

    <actuator name="LShoulderPitch_Motor">
      <hardwareInterface>PositionJointInterface</hardwareInterface>
      <mechanicalReduction>150.27</mechanicalReduction>
    </actuator>
  </transmission>
  <transmission name="LShoulderRoll_Transmission">
    <type>transmission_interface/SimpleTransmission</type>
    <joint name="LShoulderRoll">
      <hardwareInterface>PositionJointInterface</hardwareInterface>
      <dynamics damping="0.1" friction="0" />
    </joint>

    <gazebo reference="LShoulderRoll">
      <implicitSpringDamper>1</implicitSpringDamper>
    </gazebo>

    <actuator name="LShoulderRoll_Motor">
      <hardwareInterface>PositionJointInterface</hardwareInterface>
      <mechanicalReduction>173.22</mechanicalReduction>
    </actuator>
  </transmission>
  <transmission name="LElbowYaw_Transmission">
    <type>transmission_interface/SimpleTransmission</type>
    <joint name="LElbowYaw">
      <hardwareInterface>PositionJointInterface</hardwareInterface>
      <dynamics damping="0.1" friction="0" />
    </joint>

    <gazebo reference="LElbowYaw">
      <implicitSpringDamper>1</implicitSpringDamper>
    </gazebo>

    <actuator name="LElbowYaw_Motor">
      <hardwareInterface>PositionJointInterface</hardwareInterface>
      <mechanicalReduction>150.27</mechanicalReduction>
    </actuator>
  </transmission>
  <transmission name="LElbowRoll_Transmission">
    <type>transmission_interface/SimpleTransmission</type>
    <joint name="LElbowRoll">
      <hardwareInterface>PositionJointInterface</hardwareInterface>
      <dynamics damping="0.1" friction="0" />
    </joint>

    <gazebo reference="LElbowRoll">
      <implicitSpringDamper>1</implicitSpringDamper>
    </gazebo>

    <actuator name="LElbowRoll_Motor">
      <hardwareInterface>PositionJointInterface</hardwareInterface>
      <mechanicalReduction>173.22</mechanicalReduction>
    </actuator>
  </transmission>
  <transmission name="LWristYaw_Transmission">
    <type>transmission_interface/SimpleTransmission</type>
    <joint name="LWristYaw">
      <hardwareInterface>PositionJointInterface</hardwareInterface>
      <dynamics damping="0.1" friction="0" />
    </joint>

    <gazebo reference="LWristYaw">
      <implicitSpringDamper>1</implicitSpringDamper>
    </gazebo>

    <actuator name="LWristYaw_Motor">
      <hardwareInterface>PositionJointInterface</hardwareInterface>
      <mechanicalReduction>50.61</mechanicalReduction>
    </actuator>
  </transmission>
  <transmission name="LHand_Transmission">
    <type>transmission_interface/SimpleTransmission</type>
    <joint name="LHand">
      <hardwareInterface>PositionJointInterface</hardwareInterface>
      <dynamics damping="0.1" friction="0" />
    </joint>

    <gazebo reference="LHand">
      <implicitSpringDamper>1</implicitSpringDamper>
    </gazebo>

    <actuator name="LHand_Motor">
      <hardwareInterface>PositionJointInterface</hardwareInterface>
      <mechanicalReduction>36.24</mechanicalReduction>
    </actuator>
  </transmission>
  <transmission name="RShoulderPitch_Transmission">
    <type>transmission_interface/SimpleTransmission</type>
    <joint name="RShoulderPitch">
      <hardwareInterface>PositionJointInterface</hardwareInterface>
      <dynamics damping="0.1" friction="0" />
    </joint>

    <gazebo reference="RShoulderPitch">
      <implicitSpringDamper>1</implicitSpringDamper>
    </gazebo>

    <actuator name="RShoulderPitch_Motor">
      <hardwareInterface>PositionJointInterface</hardwareInterface>
      <mechanicalReduction>150.27</mechanicalReduction>
    </actuator>
  </transmission>
  <transmission name="RShoulderRoll_Transmission">
    <type>transmission_interface/SimpleTransmission</type>
    <joint name="RShoulderRoll">
      <hardwareInterface>PositionJointInterface</hardwareInterface>
      <dynamics damping="0.1" friction="0" />
    </joint>

    <gazebo reference="RShoulderRoll">
      <implicitSpringDamper>1</implicitSpringDamper>
    </gazebo>

    <actuator name="RShoulderRoll_Motor">
      <hardwareInterface>PositionJointInterface</hardwareInterface>
      <mechanicalReduction>173.22</mechanicalReduction>
    </actuator>
  </transmission>
  <transmission name="RElbowYaw_Transmission">
    <type>transmission_interface/SimpleTransmission</type>
    <joint name="RElbowYaw">
      <hardwareInterface>PositionJointInterface</hardwareInterface>
      <dynamics damping="0.1" friction="0" />
    </joint>

    <gazebo reference="RElbowYaw">
      <implicitSpringDamper>1</implicitSpringDamper>
    </gazebo>

    <actuator name="RElbowYaw_Motor">
      <hardwareInterface>PositionJointInterface</hardwareInterface>
      <mechanicalReduction>150.27</mechanicalReduction>
    </actuator>
  </transmission>
  <transmission name="RElbowRoll_Transmission">
    <type>transmission_interface/SimpleTransmission</type>
    <joint name="RElbowRoll">
      <hardwareInterface>PositionJointInterface</hardwareInterface>
      <dynamics damping="0.1" friction="0" />
    </joint>

    <gazebo reference="RElbowRoll">
      <implicitSpringDamper>1</implicitSpringDamper>
    </gazebo>

    <actuator name="RElbowRoll_Motor">
      <hardwareInterface>PositionJointInterface</hardwareInterface>
      <mechanicalReduction>173.22</mechanicalReduction>
    </actuator>
  </transmission>
  <transmission name="RWristYaw_Transmission">
    <type>transmission_interface/SimpleTransmission</type>
    <joint name="RWristYaw">
      <hardwareInterface>PositionJointInterface</hardwareInterface>
      <dynamics damping="0.1" friction="0" />
    </joint>

    <gazebo reference="RWristYaw">
      <implicitSpringDamper>1</implicitSpringDamper>
    </gazebo>

    <actuator name="RWristYaw_Motor">
      <hardwareInterface>PositionJointInterface</hardwareInterface>
      <mechanicalReduction>50.61</mechanicalReduction>
    </actuator>
  </transmission>
  <transmission name="RHand_Transmission">
    <type>transmission_interface/SimpleTransmission</type>
    <joint name="RHand">
      <hardwareInterface>PositionJointInterface</hardwareInterface>
      <dynamics damping="0.1" friction="0" />
    </joint>

    <gazebo reference="RHand">
      <implicitSpringDamper>1</implicitSpringDamper>
    </gazebo>

    <actuator name="RHand_Motor">
      <hardwareInterface>PositionJointInterface</hardwareInterface>
      <mechanicalReduction>36.24</mechanicalReduction>
    </actuator>
  </transmission>
  <transmission name="LHipYawPitch_Transmission">
    <type>transmission_interface/SimpleTransmission</type>
    <joint name="LHipYawPitch">
      <hardwareInterface>PositionJointInterface</hardwareInterface>
      <dynamics damping="0.1" friction="0" />
    </joint>


    <gazebo reference="LHipYawPitch">
      <implicitSpringDamper>1</implicitSpringDamper>
    </gazebo>

    <actuator name="LHipYawPitch_Motor">
      <!-- Dummy Values -->
      <hardwareInterface>PositionJointInterface</hardwareInterface>
      <mechanicalReduction>201.3</mechanicalReduction>
    </actuator>
  </transmission>
  <transmission name="LHipRoll_Transmission">
    <type>transmission_interface/SimpleTransmission</type>
    <joint name="LHipRoll">
      <hardwareInterface>PositionJointInterface</hardwareInterface>
      <dynamics damping="0.1" friction="0" />
    </joint>

    <gazebo reference="LHipRoll">
      <implicitSpringDamper>1</implicitSpringDamper>
    </gazebo>

    <actuator name="LHipRoll_Motor">
      <!-- Dummy Values -->
      <hardwareInterface>PositionJointInterface</hardwareInterface>
      <mechanicalReduction>201.3</mechanicalReduction>
    </actuator>
  </transmission>
  <transmission name="LHipPitch_Transmission">
    <type>transmission_interface/SimpleTransmission</type>
    <joint name="LHipPitch">
      <hardwareInterface>PositionJointInterface</hardwareInterface>
      <dynamics damping="0.1" friction="0" />
    </joint>

    <gazebo reference="LHipPitch">
      <implicitSpringDamper>1</implicitSpringDamper>
    </gazebo>

    <actuator name="LHipPitch_Motor">
      <!-- Dummy Values -->
      <hardwareInterface>PositionJointInterface</hardwareInterface>
      <mechanicalReduction>130.85</mechanicalReduction>
    </actuator>
  </transmission>
  <transmission name="LKneePitch_Transmission">
    <type>transmission_interface/SimpleTransmission</type>
    <joint name="LKneePitch">
      <hardwareInterface>PositionJointInterface</hardwareInterface>
      <dynamics damping="0.1" friction="0" />
    </joint>

    <gazebo reference="LKneePitch">
      <implicitSpringDamper>1</implicitSpringDamper>
    </gazebo>

    <actuator name="LKneePitch_Motor">
      <!-- Dummy Values -->
      <hardwareInterface>PositionJointInterface</hardwareInterface>
      <mechanicalReduction>130.85</mechanicalReduction>
    </actuator>
  </transmission>
  <transmission name="LAnklePitch_Transmission">
    <type>transmission_interface/SimpleTransmission</type>
    <joint name="LAnklePitch">
      <hardwareInterface>PositionJointInterface</hardwareInterface>
      <dynamics damping="0.1" friction="0" />
    </joint>

    <gazebo reference="LAnklePitch">
      <implicitSpringDamper>1</implicitSpringDamper>
    </gazebo>

    <actuator name="LAnklePitch_Motor">
      <!-- Dummy Values -->
      <hardwareInterface>PositionJointInterface</hardwareInterface>
      <mechanicalReduction>130.85</mechanicalReduction>
    </actuator>
  </transmission>
  <transmission name="LAnkleRoll_Transmission">
    <type>transmission_interface/SimpleTransmission</type>
    <joint name="LAnkleRoll">
      <hardwareInterface>PositionJointInterface</hardwareInterface>
      <dynamics damping="0.1" friction="0" />
    </joint>

    <gazebo reference="LAnkleRoll">
      <implicitSpringDamper>1</implicitSpringDamper>
    </gazebo>

    <actuator name="LAnkleRoll_Motor">
      <!-- Dummy Values -->
      <hardwareInterface>PositionJointInterface</hardwareInterface>
      <mechanicalReduction>201.3</mechanicalReduction>
    </actuator>
  </transmission>
  <transmission name="RHipYawPitch_Transmission">
    <type>transmission_interface/SimpleTransmission</type>
    <joint name="RHipYawPitch">
      <hardwareInterface>PositionJointInterface</hardwareInterface>
      <dynamics damping="0.1" friction="0" />
    </joint>

    <gazebo reference="RHipYawPitch">
      <implicitSpringDamper>1</implicitSpringDamper>
    </gazebo>

    <actuator name="RHipYawPitch_Motor">
      <!-- Dummy Values -->
      <hardwareInterface>PositionJointInterface</hardwareInterface>
      <mechanicalReduction>201.3</mechanicalReduction>
    </actuator>
  </transmission>
  <transmission name="RHipRoll_Transmission">
    <type>transmission_interface/SimpleTransmission</type>
    <joint name="RHipRoll">
      <hardwareInterface>PositionJointInterface</hardwareInterface>
      <dynamics damping="0.1" friction="0" />
    </joint>

    <gazebo reference="RHipRoll">
      <implicitSpringDamper>1</implicitSpringDamper>
    </gazebo>

    <actuator name="RHipRoll_Motor">
      <!-- Dummy Values -->
      <hardwareInterface>PositionJointInterface</hardwareInterface>
      <mechanicalReduction>201.3</mechanicalReduction>
    </actuator>
  </transmission>
  <transmission name="RHipPitch_Transmission">
    <type>transmission_interface/SimpleTransmission</type>
    <joint name="RHipPitch">
      <hardwareInterface>PositionJointInterface</hardwareInterface>
      <dynamics damping="0.1" friction="0" />
    </joint>

    <gazebo reference="RHipPitch">
      <implicitSpringDamper>1</implicitSpringDamper>
    </gazebo>

    <actuator name="RHipPitch_Motor">
      <!-- Dummy Values -->
      <hardwareInterface>PositionJointInterface</hardwareInterface>
      <mechanicalReduction>130.85</mechanicalReduction>
    </actuator>
  </transmission>
  <transmission name="RKneePitch_Transmission">
    <type>transmission_interface/SimpleTransmission</type>
    <joint name="RKneePitch">
      <hardwareInterface>PositionJointInterface</hardwareInterface>
      <dynamics damping="0.1" friction="0" />
    </joint>

    <gazebo reference="RKneePitch">
      <implicitSpringDamper>1</implicitSpringDamper>
    </gazebo>

    <actuator name="RKneePitch_Motor">
      <!-- Dummy Values -->
      <hardwareInterface>PositionJointInterface</hardwareInterface>
      <mechanicalReduction>130.85</mechanicalReduction>
    </actuator>
  </transmission>
  <transmission name="RAnklePitch_Transmission">
    <type>transmission_interface/SimpleTransmission</type>
    <joint name="RAnklePitch">
      <hardwareInterface>PositionJointInterface</hardwareInterface>
      <dynamics damping="0.1" friction="0" />
    </joint>

    <gazebo reference="RAnklePitch">
      <implicitSpringDamper>1</implicitSpringDamper>
    </gazebo>

    <actuator name="RAnklePitch_Motor">
      <!-- Dummy Values -->
      <hardwareInterface>PositionJointInterface</hardwareInterface>
      <mechanicalReduction>130.85</mechanicalReduction>
    </actuator>
  </transmission>
  <transmission name="RAnkleRoll_Transmission">
    <type>transmission_interface/SimpleTransmission</type>
    <joint name="RAnkleRoll">
      <hardwareInterface>PositionJointInterface</hardwareInterface>
      <dynamics damping="0.1" friction="0" />
    </joint>

    <gazebo reference="RAnkleRoll">
      <implicitSpringDamper>1</implicitSpringDamper>
    </gazebo>

    <actuator name="RAnkleRoll_Motor">
      <!-- Dummy Values -->
      <hardwareInterface>PositionJointInterface</hardwareInterface>
      <mechanicalReduction>201.3</mechanicalReduction>
    </actuator>
  </transmission>
  <gazebo>
    <!-- <plugin filename="libgazebo_ros_control.so" name="gazebo_ros_control">
      <robotNamespace>/nao_dcm</robotNamespace>
      <robotSimType>gazebo_ros_control/DefaultRobotHWSim</robotSimType>
    </plugin> -->
    <plugin filename="libgazebo_naoqi_control.so" name="gazebo_ros_control">
      <robotNamespace>/nao_dcm</robotNamespace>
    </plugin>
    <!-- <plugin filename="libgazebo_ros_imu.so" name="gazebo_ros_imu_controller">
      <robotNamespace>/nao_dcm</robotNamespace>
      <topicName>imu_data</topicName>
      <bodyName>imu</bodyName>
      <frameId>imu</frameId>
      <gaussianNoise>2.89e-08</gaussianNoise>
      <accelGaussianNoise>2.89e-08 2.89e-08 2.89e-08</accelGaussianNoise>
      <rateGaussianNoise>2.89e-08 2.89e-08 2.89e-08</rateGaussianNoise>
      <headingGaussianNoise>2.89e-08 2.89e-08 2.89e-08</headingGaussianNoise>
      <xyzOffsets>0 0 0</xyzOffsets>
      <rpyOffsets>0 0 0</rpyOffsets>
      <updateRate>30.0</updateRate>
      <alwaysOn>true</alwaysOn>
    </plugin> -->
    <!--        <plugin name="gazebo_ros_imu_controller" filename="${imu_plugin}">
            <robotNamespace>/nao_dcm</robotNamespace>
            <topicName>imu_data</topicName>
            <bodyName>imu</bodyName>
            <frameId>imu</frameId>
            <gaussianNoise>2.89e-08</gaussianNoise>
            <accelGaussianNoise>2.89e-08 2.89e-08 2.89e-08</accelGaussianNoise>
            <rateGaussianNoise>2.89e-08 2.89e-08 2.89e-08</rateGaussianNoise>
            <headingGaussianNoise>2.89e-08 2.89e-08 2.89e-08</headingGaussianNoise>
            <xyzOffsets>0 0 0</xyzOffsets>
            <rpyOffsets>0 0 0</rpyOffsets>
            <updateRate>30.0</updateRate>
            <alwaysOn>true</alwaysOn>
        </plugin>
-->
    <!-- Mimic joints through plugin develop by costashatz based on implementation by Goncalo Cabrita -->
    <!-- <plugin filename="libroboticsgroup_gazebo_mimic_joint_plugin.so" name="mimic_hipyawpitch">
      <joint>LHipYawPitch</joint>
      <mimicJoint>RHipYawPitch</mimicJoint>
      <multiplier>1.0</multiplier>
      <offset>0.0</offset>
    </plugin>
    <plugin filename="libroboticsgroup_gazebo_mimic_joint_plugin.so" name="mimic_LFinger1">
      <joint>LHand</joint>
      <mimicJoint>LFinger1</mimicJoint>
      <multiplier>-0.785398163398</multiplier>
      <offset>0.785398163398</offset>
    </plugin>
    <plugin filename="libroboticsgroup_gazebo_mimic_joint_plugin.so" name="mimic_LFinger11">
      <joint>LHand</joint>
      <mimicJoint>LFinger11</mimicJoint>
      <multiplier>-0.785398163398</multiplier>
      <offset>0.785398163398</offset>
    </plugin>
    <plugin filename="libroboticsgroup_gazebo_mimic_joint_plugin.so" name="mimic_LFinger12">
      <joint>LHand</joint>
      <mimicJoint>LFinger12</mimicJoint>
      <multiplier>-0.785398163398</multiplier>
      <offset>0.785398163398</offset>
    </plugin>
    <plugin filename="libroboticsgroup_gazebo_mimic_joint_plugin.so" name="mimic_LFinger2">
      <joint>LHand</joint>
      <mimicJoint>LFinger2</mimicJoint>
      <multiplier>-0.785398163398</multiplier>
      <offset>0.785398163398</offset>
    </plugin>
    <plugin filename="libroboticsgroup_gazebo_mimic_joint_plugin.so" name="mimic_LFinger21">
      <joint>LHand</joint>
      <mimicJoint>LFinger21</mimicJoint>
      <multiplier>-0.785398163398</multiplier>
      <offset>0.785398163398</offset>
    </plugin>
    <plugin filename="libroboticsgroup_gazebo_mimic_joint_plugin.so" name="mimic_LFinger22">
      <joint>LHand</joint>
      <mimicJoint>LFinger22</mimicJoint>
      <multiplier>-0.785398163398</multiplier>
      <offset>0.785398163398</offset>
    </plugin>
    <plugin filename="libroboticsgroup_gazebo_mimic_joint_plugin.so" name="mimic_RFinger1">
      <joint>RHand</joint>
      <mimicJoint>RFinger1</mimicJoint>
      <multiplier>-0.785398163398</multiplier>
      <offset>0.785398163398</offset>
    </plugin>
    <plugin filename="libroboticsgroup_gazebo_mimic_joint_plugin.so" name="mimic_RFinger11">
      <joint>RHand</joint>
      <mimicJoint>RFinger11</mimicJoint>
      <multiplier>-0.785398163398</multiplier>
      <offset>0.785398163398</offset>
    </plugin>
    <plugin filename="libroboticsgroup_gazebo_mimic_joint_plugin.so" name="mimic_RFinger12">
      <joint>RHand</joint>
      <mimicJoint>RFinger12</mimicJoint>
      <multiplier>-0.785398163398</multiplier>
      <offset>0.785398163398</offset>
    </plugin>
    <plugin filename="libroboticsgroup_gazebo_mimic_joint_plugin.so" name="mimic_RFinger2">
      <joint>RHand</joint>
      <mimicJoint>RFinger2</mimicJoint>
      <multiplier>-0.785398163398</multiplier>
      <offset>0.785398163398</offset>
    </plugin>
    <plugin filename="libroboticsgroup_gazebo_mimic_joint_plugin.so" name="mimic_RFinger21">
      <joint>RHand</joint>
      <mimicJoint>RFinger21</mimicJoint>
      <multiplier>-0.785398163398</multiplier>
      <offset>0.785398163398</offset>
    </plugin>
    <plugin filename="libroboticsgroup_gazebo_mimic_joint_plugin.so" name="mimic_RFinger22">
      <joint>RHand</joint>
      <mimicJoint>RFinger22</mimicJoint>
      <multiplier>-0.785398163398</multiplier>
      <offset>0.785398163398</offset>
    </plugin>
    <plugin filename="libroboticsgroup_gazebo_mimic_joint_plugin.so" name="LThumb1">
      <joint>LHand</joint>
      <mimicJoint>LThumb1</mimicJoint>
      <multiplier>-0.785398163398</multiplier>
      <offset>0.785398163398</offset>
    </plugin>
    <plugin filename="libroboticsgroup_gazebo_mimic_joint_plugin.so" name="LThumb12">
      <joint>LHand</joint>
      <mimicJoint>LThumb12</mimicJoint>
      <multiplier>-0.785398163398</multiplier>
      <offset>0.785398163398</offset>
    </plugin>
    <plugin filename="libroboticsgroup_gazebo_mimic_joint_plugin.so" name="RThumb1">
      <joint>RHand</joint>
      <mimicJoint>RThumb1</mimicJoint>
      <multiplier>-0.785398163398</multiplier>
      <offset>0.785398163398</offset>
    </plugin>
    <plugin filename="libroboticsgroup_gazebo_mimic_joint_plugin.so" name="RThumb12">
      <joint>RHand</joint>
      <mimicJoint>RThumb12</mimicJoint>
      <multiplier>-0.785398163398</multiplier>
      <offset>0.785398163398</offset>
    </plugin>
    <plugin filename="libroboticsgroup_gazebo_disable_link_plugin.so" name="LFinger11_link">
      <link>LFinger11_link</link>
    </plugin>
    <plugin filename="libroboticsgroup_gazebo_disable_link_plugin.so" name="LFinger12_link">
      <link>LFinger12_link</link>
    </plugin>
    <plugin filename="libroboticsgroup_gazebo_disable_link_plugin.so" name="LFinger13_link">
      <link>LFinger13_link</link>
    </plugin>
    <plugin filename="libroboticsgroup_gazebo_disable_link_plugin.so" name="LFinger21_link">
      <link>LFinger21_link</link>
    </plugin>
    <plugin filename="libroboticsgroup_gazebo_disable_link_plugin.so" name="LFinger22_link">
      <link>LFinger22_link</link>
    </plugin>
    <plugin filename="libroboticsgroup_gazebo_disable_link_plugin.so" name="LFinger23_link">
      <link>LFinger23_link</link>
    </plugin>
    <plugin filename="libroboticsgroup_gazebo_disable_link_plugin.so" name="LThumb1_link">
      <link>LThumb1_link</link>
    </plugin>
    <plugin filename="libroboticsgroup_gazebo_disable_link_plugin.so" name="LThumb2_link">
      <link>LThumb2_link</link>
    </plugin>
    <plugin filename="libroboticsgroup_gazebo_disable_link_plugin.so" name="l_gripper">
      <link>l_gripper</link>
    </plugin>
    <plugin filename="libroboticsgroup_gazebo_disable_link_plugin.so" name="RFinger11_link">
      <link>RFinger11_link</link>
    </plugin>
    <plugin filename="libroboticsgroup_gazebo_disable_link_plugin.so" name="RFinger12_link">
      <link>RFinger12_link</link>
    </plugin>
    <plugin filename="libroboticsgroup_gazebo_disable_link_plugin.so" name="RFinger13_link">
      <link>RFinger13_link</link>
    </plugin>
    <plugin filename="libroboticsgroup_gazebo_disable_link_plugin.so" name="RFinger21_link">
      <link>RFinger21_link</link>
    </plugin>
    <plugin filename="libroboticsgroup_gazebo_disable_link_plugin.so" name="RFinger22_link">
      <link>RFinger22_link</link>
    </plugin>
    <plugin filename="libroboticsgroup_gazebo_disable_link_plugin.so" name="RFinger23_link">
      <link>RFinger23_link</link>
    </plugin>
    <plugin filename="libroboticsgroup_gazebo_disable_link_plugin.so" name="RThumb1_link">
      <link>RThumb1_link</link>
    </plugin>
    <plugin filename="libroboticsgroup_gazebo_disable_link_plugin.so" name="RThumb2_link">
      <link>RThumb2_link</link>
    </plugin>
    <plugin filename="libroboticsgroup_gazebo_disable_link_plugin.so" name="r_gripper">
      <link>r_gripper</link>
    </plugin> -->
  </gazebo>
  <gazebo reference="torso">
    <mu1>0.5</mu1>
    <mu2>0.5</mu2>
    <selfCollide>false</selfCollide>
    <turnGravityOff>false</turnGravityOff>
  </gazebo>
  <gazebo reference="Neck">
    <mu1>0.5</mu1>
    <mu2>0.5</mu2>
    <selfCollide>false</selfCollide>
    <turnGravityOff>false</turnGravityOff>
  </gazebo>
  <gazebo reference="Head">
    <mu1>0.5</mu1>
    <mu2>0.5</mu2>
    <selfCollide>false</selfCollide>
    <turnGravityOff>false</turnGravityOff>
  </gazebo>
  <gazebo reference="gaze">
    <mu1>0.5</mu1>
    <mu2>0.5</mu2>
    <selfCollide>false</selfCollide>
    <turnGravityOff>false</turnGravityOff>
  </gazebo>
  <gazebo reference="LShoulder">
    <mu1>0.5</mu1>
    <mu2>0.5</mu2>
    <selfCollide>false</selfCollide>
    <turnGravityOff>false</turnGravityOff>
  </gazebo>
  <gazebo reference="LBicep">
    <mu1>0.5</mu1>
    <mu2>0.5</mu2>
    <selfCollide>false</selfCollide>
    <turnGravityOff>false</turnGravityOff>
  </gazebo>
  <gazebo reference="LElbow">
    <mu1>0.5</mu1>
    <mu2>0.5</mu2>
    <selfCollide>false</selfCollide>
    <turnGravityOff>false</turnGravityOff>
  </gazebo>
  <gazebo reference="LForeArm">
    <mu1>0.5</mu1>
    <mu2>0.5</mu2>
    <selfCollide>false</selfCollide>
    <turnGravityOff>false</turnGravityOff>
  </gazebo>
  <gazebo reference="l_wrist">
    <mu1>0.5</mu1>
    <mu2>0.5</mu2>
    <selfCollide>false</selfCollide>
    <turnGravityOff>false</turnGravityOff>
  </gazebo>
  <gazebo reference="l_gripper">
    <mu1>0.5</mu1>
    <mu2>0.5</mu2>
    <selfCollide>false</selfCollide>
    <turnGravityOff>true</turnGravityOff>
  </gazebo>
  <gazebo reference="RShoulder">
    <mu1>0.5</mu1>
    <mu2>0.5</mu2>
    <selfCollide>false</selfCollide>
    <turnGravityOff>false</turnGravityOff>
  </gazebo>
  <gazebo reference="RBicep">
    <mu1>0.5</mu1>
    <mu2>0.5</mu2>
    <selfCollide>false</selfCollide>
    <turnGravityOff>false</turnGravityOff>
  </gazebo>
  <gazebo reference="RElbow">
    <mu1>0.5</mu1>
    <mu2>0.5</mu2>
    <selfCollide>false</selfCollide>
    <turnGravityOff>false</turnGravityOff>
  </gazebo>
  <gazebo reference="RForeArm">
    <mu1>0.5</mu1>
    <mu2>0.5</mu2>
    <selfCollide>false</selfCollide>
    <turnGravityOff>false</turnGravityOff>
  </gazebo>
  <gazebo reference="r_wrist">
    <mu1>0.5</mu1>
    <mu2>0.5</mu2>
    <selfCollide>false</selfCollide>
    <turnGravityOff>false</turnGravityOff>
  </gazebo>
  <gazebo reference="r_gripper">
    <mu1>0.5</mu1>
    <mu2>0.5</mu2>
    <selfCollide>false</selfCollide>
    <turnGravityOff>true</turnGravityOff>
  </gazebo>
  <gazebo reference="LFinger11_link">
    <mu1>0.5</mu1>
    <mu2>0.5</mu2>
    <selfCollide>false</selfCollide>
    <turnGravityOff>true</turnGravityOff>
  </gazebo>
  <gazebo reference="LFinger12_link">
    <mu1>0.5</mu1>
    <mu2>0.5</mu2>
    <selfCollide>false</selfCollide>
    <turnGravityOff>true</turnGravityOff>
  </gazebo>
  <gazebo reference="LFinger13_link">
    <mu1>0.5</mu1>
    <mu2>0.5</mu2>
    <selfCollide>false</selfCollide>
    <turnGravityOff>true</turnGravityOff>
  </gazebo>
  <gazebo reference="LFinger21_link">
    <mu1>0.5</mu1>
    <mu2>0.5</mu2>
    <selfCollide>false</selfCollide>
    <turnGravityOff>true</turnGravityOff>
  </gazebo>
  <gazebo reference="LFinger22_link">
    <mu1>0.5</mu1>
    <mu2>0.5</mu2>
    <selfCollide>false</selfCollide>
    <turnGravityOff>true</turnGravityOff>
  </gazebo>
  <gazebo reference="LFinger23_link">
    <mu1>0.5</mu1>
    <mu2>0.5</mu2>
    <selfCollide>false</selfCollide>
    <turnGravityOff>true</turnGravityOff>
  </gazebo>
  <gazebo reference="LThumb1_link">
    <mu1>0.5</mu1>
    <mu2>0.5</mu2>
    <selfCollide>false</selfCollide>
    <turnGravityOff>true</turnGravityOff>
  </gazebo>
  <gazebo reference="LThumb2_link">
    <mu1>0.5</mu1>
    <mu2>0.5</mu2>
    <selfCollide>false</selfCollide>
    <turnGravityOff>true</turnGravityOff>
  </gazebo>
  <gazebo reference="LPelvis">
    <mu1>0.5</mu1>
    <mu2>0.5</mu2>
    <selfCollide>false</selfCollide>
    <turnGravityOff>false</turnGravityOff>
  </gazebo>
  <gazebo reference="LHip">
    <mu1>0.5</mu1>
    <mu2>0.5</mu2>
    <selfCollide>false</selfCollide>
    <turnGravityOff>false</turnGravityOff>
  </gazebo>
  <gazebo reference="LThigh">
    <mu1>0.5</mu1>
    <mu2>0.5</mu2>
    <selfCollide>false</selfCollide>
    <turnGravityOff>false</turnGravityOff>
  </gazebo>
  <gazebo reference="LTibia">
    <mu1>0.5</mu1>
    <mu2>0.5</mu2>
    <selfCollide>false</selfCollide>
    <turnGravityOff>false</turnGravityOff>
  </gazebo>
  <gazebo reference="l_ankle">
    <mu1>0.5</mu1>
    <mu2>0.5</mu2>
    <selfCollide>false</selfCollide>
    <turnGravityOff>false</turnGravityOff>
  </gazebo>
  <gazebo reference="l_sole">
    <mu1>0.5</mu1>
    <mu2>0.5</mu2>
    <selfCollide>false</selfCollide>
    <turnGravityOff>false</turnGravityOff>
    <fdir1>1 0 0</fdir1>
    <maxVel>0.1</maxVel>
    <minDepth>0.003</minDepth>
  </gazebo>
  <gazebo reference="RPelvis">
    <mu1>0.5</mu1>
    <mu2>0.5</mu2>
    <selfCollide>false</selfCollide>
    <turnGravityOff>false</turnGravityOff>
  </gazebo>
  <gazebo reference="RHip">
    <mu1>0.5</mu1>
    <mu2>0.5</mu2>
    <selfCollide>false</selfCollide>
    <turnGravityOff>false</turnGravityOff>
  </gazebo>
  <gazebo reference="RThigh">
    <mu1>0.5</mu1>
    <mu2>0.5</mu2>
    <selfCollide>false</selfCollide>
    <turnGravityOff>false</turnGravityOff>
  </gazebo>
  <gazebo reference="RTibia">
    <mu1>0.5</mu1>
    <mu2>0.5</mu2>
    <selfCollide>false</selfCollide>
    <turnGravityOff>false</turnGravityOff>
  </gazebo>
  <gazebo reference="r_ankle">
    <mu1>0.5</mu1>
    <mu2>0.5</mu2>
    <selfCollide>false</selfCollide>
    <turnGravityOff>false</turnGravityOff>
  </gazebo>
  <gazebo reference="r_sole">
    <mu1>0.5</mu1>
    <mu2>0.5</mu2>
    <selfCollide>false</selfCollide>
    <turnGravityOff>false</turnGravityOff>
    <fdir1>1 0 0</fdir1>
    <maxVel>0.1</maxVel>
    <minDepth>0.003</minDepth>
  </gazebo>
  <gazebo reference="RFinger11_link">
    <mu1>0.5</mu1>
    <mu2>0.5</mu2>
    <selfCollide>false</selfCollide>
    <turnGravityOff>true</turnGravityOff>
  </gazebo>
  <gazebo reference="RFinger12_link">
    <mu1>0.5</mu1>
    <mu2>0.5</mu2>
    <selfCollide>false</selfCollide>
    <turnGravityOff>true</turnGravityOff>
  </gazebo>
  <gazebo reference="RFinger13_link">
    <mu1>0.5</mu1>
    <mu2>0.5</mu2>
    <selfCollide>false</selfCollide>
    <turnGravityOff>true</turnGravityOff>
  </gazebo>
  <gazebo reference="RFinger21_link">
    <mu1>0.5</mu1>
    <mu2>0.5</mu2>
    <selfCollide>false</selfCollide>
    <turnGravityOff>true</turnGravityOff>
  </gazebo>
  <gazebo reference="RFinger22_link">
    <mu1>0.5</mu1>
    <mu2>0.5</mu2>
    <selfCollide>false</selfCollide>
    <turnGravityOff>true</turnGravityOff>
  </gazebo>
  <gazebo reference="RFinger23_link">
    <mu1>0.5</mu1>
    <mu2>0.5</mu2>
    <selfCollide>false</selfCollide>
    <turnGravityOff>true</turnGravityOff>
  </gazebo>
  <gazebo reference="RThumb1_link">
    <mu1>0.5</mu1>
    <mu2>0.5</mu2>
    <selfCollide>false</selfCollide>
    <turnGravityOff>true</turnGravityOff>
  </gazebo>
  <gazebo reference="RThumb2_link">
    <mu1>0.5</mu1>
    <mu2>0.5</mu2>
    <selfCollide>false</selfCollide>
    <turnGravityOff>true</turnGravityOff>
  </gazebo>
  <joint name="torso-imu" type="fixed">
    <parent link="torso"/>
    <child link="imu"/>
    <!-- Accelerometer -->
    <origin rpy="0 0 0" xyz="-0.008 0.00606 0.027"/>
    <!-- Gyrometer -->
    <!-- <origin xyz="-0.008 0.006 0.029" rpy="0 0 0"/> -->
  </joint>
  <link name="imu"/>
  <joint name="LFinger1" type="revolute">
    <parent link="l_wrist"/>
    <child link="LFinger11_link"/>
    <origin rpy="0 0 0" xyz="0.06907 0.01157 -0.00304"/>
    <axis xyz="0 1 0"/>
    <mimic joint="LHand" multiplier="-0.785398163398" offset="0.785398163398"/>
    <limit effort="10.0" lower="0.0" upper="0.785398163398" velocity="3.0"/>
    <dynamics damping="0.1" friction="0" />
  </joint>

  <gazebo reference="LFinger1">
    <implicitSpringDamper>1</implicitSpringDamper>
  </gazebo>

  <link name="LFinger11_link">
    <visual>
      <origin rpy="0 -0 0" xyz="0 0 0"/>
      <geometry>
        <mesh filename="package://nao_meshes/meshes/V40/LFinger11.dae" scale="0.1 0.1 0.1"/>
      </geometry>
    </visual>
    <collision>
      <origin rpy="0 -0 0" xyz="0 0 0"/>
      <geometry>
        <mesh filename="package://nao_meshes/meshes/V40/LFinger11_0.10.stl" scale="0.1 0.1 0.1"/>
      </geometry>
    </collision>
    <inertial>
      <mass value="0.2e-5"/>
      <origin xyz="0 0 0"/>
      <inertia ixx="1e-9" ixy="0" ixz="0" iyy="1e-9" iyz="0" izz="1e-9"/>
    </inertial>
  </link>
  <joint name="LFinger11" type="revolute">
    <parent link="LFinger11_link"/>
    <child link="LFinger12_link"/>
    <origin rpy="0 0 0" xyz="0.01436 0 0"/>
    <axis xyz="0 1 0"/>
    <mimic joint="LHand" multiplier="-0.785398163398" offset="0.785398163398"/>
    <limit effort="10.0" lower="0.0" upper="0.785398163398" velocity="3.0"/>
    <dynamics damping="0.1" friction="0" />
  </joint>

  <gazebo reference="LFinger11">
    <implicitSpringDamper>1</implicitSpringDamper>
  </gazebo>

  <link name="LFinger12_link">
    <visual>
      <origin rpy="0 -0 0" xyz="0 0 0"/>
      <geometry>
        <mesh filename="package://nao_meshes/meshes/V40/LFinger12.dae" scale="0.1 0.1 0.1"/>
      </geometry>
    </visual>
    <collision>
      <origin rpy="0 -0 0" xyz="0 0 0"/>
      <geometry>
        <mesh filename="package://nao_meshes/meshes/V40/LFinger12_0.10.stl" scale="0.1 0.1 0.1"/>
      </geometry>
    </collision>
    <inertial>
      <mass value="0.2e-5"/>
      <origin xyz="0 0 0"/>
      <inertia ixx="1e-9" ixy="0" ixz="0" iyy="1e-9" iyz="0" izz="1e-9"/>
    </inertial>
  </link>
  <joint name="LFinger12" type="revolute">
    <parent link="LFinger12_link"/>
    <child link="LFinger13_link"/>
    <origin rpy="0 0 0" xyz="0.01436 0 0"/>
    <axis xyz="0 1 0"/>
    <mimic joint="LHand" multiplier="-0.785398163398" offset="0.785398163398"/>
    <limit effort="10.0" lower="0.0" upper="0.785398163398" velocity="3.0"/>
    <dynamics damping="0.1" friction="0" />
  </joint>

  <gazebo reference="LFinger12">
    <implicitSpringDamper>1</implicitSpringDamper>
  </gazebo>

  <link name="LFinger13_link">
    <visual>
      <origin rpy="0 -0 0" xyz="0 0 0"/>
      <geometry>
        <mesh filename="package://nao_meshes/meshes/V40/LFinger13.dae" scale="0.1 0.1 0.1"/>
      </geometry>
    </visual>
    <collision>
      <origin rpy="0 -0 0" xyz="0 0 0"/>
      <geometry>
        <mesh filename="package://nao_meshes/meshes/V40/LFinger13_0.10.stl" scale="0.1 0.1 0.1"/>
      </geometry>
    </collision>
    <inertial>
      <mass value="0.2e-5"/>
      <origin xyz="0 0 0"/>
      <inertia ixx="1e-9" ixy="0" ixz="0" iyy="1e-9" iyz="0" izz="1e-9"/>
    </inertial>
  </link>
  <joint name="LFinger2" type="revolute">
    <parent link="l_wrist"/>
    <child link="LFinger21_link"/>
    <origin rpy="0 0 0" xyz="0.06907 -0.01157 -0.00304"/>
    <axis xyz="0 1 0"/>
    <mimic joint="LHand" multiplier="-0.785398163398" offset="0.785398163398"/>
    <limit effort="10.0" lower="0.0" upper="0.785398163398" velocity="3.0"/>
    <dynamics damping="0.1" friction="0" />
  </joint>

  <gazebo reference="LFinger2">
    <implicitSpringDamper>1</implicitSpringDamper>
  </gazebo>

  <link name="LFinger21_link">
    <visual>
      <origin rpy="0 -0 0" xyz="0 0 0"/>
      <geometry>
        <mesh filename="package://nao_meshes/meshes/V40/LFinger21.dae" scale="0.1 0.1 0.1"/>
      </geometry>
    </visual>
    <collision>
      <origin rpy="0 -0 0" xyz="0 0 0"/>
      <geometry>
        <mesh filename="package://nao_meshes/meshes/V40/LFinger21_0.10.stl" scale="0.1 0.1 0.1"/>
      </geometry>
    </collision>
    <inertial>
      <mass value="0.2e-5"/>
      <origin xyz="0 0 0"/>
      <inertia ixx="1e-9" ixy="0" ixz="0" iyy="1e-9" iyz="0" izz="1e-9"/>
    </inertial>
  </link>
  <joint name="LFinger21" type="revolute">
    <parent link="LFinger21_link"/>
    <child link="LFinger22_link"/>
    <origin rpy="0 0 0" xyz="0.01436 0 0"/>
    <axis xyz="0 1 0"/>
    <mimic joint="LHand" multiplier="-0.785398163398" offset="0.785398163398"/>
    <limit effort="10.0" lower="0.0" upper="0.785398163398" velocity="3.0"/>
    <dynamics damping="0.1" friction="0" />
  </joint>

  <gazebo reference="LFinger21">
    <implicitSpringDamper>1</implicitSpringDamper>
  </gazebo>

  <link name="LFinger22_link">
    <visual>
      <origin rpy="0 -0 0" xyz="0 0 0"/>
      <geometry>
        <mesh filename="package://nao_meshes/meshes/V40/LFinger22.dae" scale="0.1 0.1 0.1"/>
      </geometry>
    </visual>
    <collision>
      <origin rpy="0 -0 0" xyz="0 0 0"/>
      <geometry>
        <mesh filename="package://nao_meshes/meshes/V40/LFinger22_0.10.stl" scale="0.1 0.1 0.1"/>
      </geometry>
    </collision>
    <inertial>
      <mass value="0.2e-5"/>
      <origin xyz="0 0 0"/>
      <inertia ixx="1e-9" ixy="0" ixz="0" iyy="1e-9" iyz="0" izz="1e-9"/>
    </inertial>
  </link>
  <joint name="LFinger22" type="revolute">
    <parent link="LFinger22_link"/>
    <child link="LFinger23_link"/>
    <origin rpy="0 0 0" xyz="0.01436 0 0"/>
    <axis xyz="0 1 0"/>
    <mimic joint="LHand" multiplier="-0.785398163398" offset="0.785398163398"/>
    <limit effort="10.0" lower="0.0" upper="0.785398163398" velocity="3.0"/>
    <dynamics damping="0.1" friction="0" />
  </joint>

  <gazebo reference="LFinger22">
    <implicitSpringDamper>1</implicitSpringDamper>
  </gazebo>

  <link name="LFinger23_link">
    <visual>
      <origin rpy="0 -0 0" xyz="0 0 0"/>
      <geometry>
        <mesh filename="package://nao_meshes/meshes/V40/LFinger23.dae" scale="0.1 0.1 0.1"/>
      </geometry>
    </visual>
    <collision>
      <origin rpy="0 -0 0" xyz="0 0 0"/>
      <geometry>
        <mesh filename="package://nao_meshes/meshes/V40/LFinger23_0.10.stl" scale="0.1 0.1 0.1"/>
      </geometry>
    </collision>
    <inertial>
      <mass value="0.2e-5"/>
      <origin xyz="0 0 0"/>
      <inertia ixx="1e-9" ixy="0" ixz="0" iyy="1e-9" iyz="0" izz="1e-9"/>
    </inertial>
  </link>
  <joint name="RFinger1" type="revolute">
    <parent link="r_wrist"/>
    <child link="RFinger11_link"/>
    <origin rpy="0 0 0" xyz="0.06907 0.01157 -0.00304"/>
    <axis xyz="0 1 0"/>
    <mimic joint="RHand" multiplier="-0.785398163398" offset="0.785398163398"/>
    <limit effort="10.0" lower="0.0" upper="0.785398163398" velocity="3.0"/>
    <dynamics damping="0.1" friction="0" />
  </joint>

  <gazebo reference="RFinger1">
    <implicitSpringDamper>1</implicitSpringDamper>
  </gazebo>

  <link name="RFinger11_link">
    <visual>
      <origin rpy="0 -0 0" xyz="0 0 0"/>
      <geometry>
        <mesh filename="package://nao_meshes/meshes/V40/RFinger11.dae" scale="0.1 0.1 0.1"/>
      </geometry>
    </visual>
    <collision>
      <origin rpy="0 -0 0" xyz="0 0 0"/>
      <geometry>
        <mesh filename="package://nao_meshes/meshes/V40/RFinger11_0.10.stl" scale="0.1 0.1 0.1"/>
      </geometry>
    </collision>
    <inertial>
      <mass value="0.2e-5"/>
      <origin xyz="0 0 0"/>
      <inertia ixx="1e-9" ixy="0" ixz="0" iyy="1e-9" iyz="0" izz="1e-9"/>
    </inertial>
  </link>
  <joint name="RFinger11" type="revolute">
    <parent link="RFinger11_link"/>
    <child link="RFinger12_link"/>
    <origin rpy="0 0 0" xyz="0.01436 0 0"/>
    <axis xyz="0 1 0"/>
    <mimic joint="RHand" multiplier="-0.785398163398" offset="0.785398163398"/>
    <limit effort="10.0" lower="0.0" upper="0.785398163398" velocity="3.0"/>
    <dynamics damping="0.1" friction="0" />
  </joint>

  <gazebo reference="RFinger11">
    <implicitSpringDamper>1</implicitSpringDamper>
  </gazebo>

  <link name="RFinger12_link">
    <visual>
      <origin rpy="0 -0 0" xyz="0 0 0"/>
      <geometry>
        <mesh filename="package://nao_meshes/meshes/V40/RFinger12.dae" scale="0.1 0.1 0.1"/>
      </geometry>
    </visual>
    <collision>
      <origin rpy="0 -0 0" xyz="0 0 0"/>
      <geometry>
        <mesh filename="package://nao_meshes/meshes/V40/RFinger12_0.10.stl" scale="0.1 0.1 0.1"/>
      </geometry>
    </collision>
    <inertial>
      <mass value="0.2e-5"/>
      <origin xyz="0 0 0"/>
      <inertia ixx="1e-9" ixy="0" ixz="0" iyy="1e-9" iyz="0" izz="1e-9"/>
    </inertial>
  </link>
  <joint name="RFinger12" type="revolute">
    <parent link="RFinger12_link"/>
    <child link="RFinger13_link"/>
    <origin rpy="0 0 0" xyz="0.01436 0 0"/>
    <axis xyz="0 1 0"/>
    <mimic joint="RHand" multiplier="-0.785398163398" offset="0.785398163398"/>
    <limit effort="10.0" lower="0.0" upper="0.785398163398" velocity="3.0"/>
    <dynamics damping="0.1" friction="0" />
  </joint>

  <gazebo reference="RFinger12">
    <implicitSpringDamper>1</implicitSpringDamper>
  </gazebo>

  <link name="RFinger13_link">
    <visual>
      <origin rpy="0 -0 0" xyz="0 0 0"/>
      <geometry>
        <mesh filename="package://nao_meshes/meshes/V40/RFinger13.dae" scale="0.1 0.1 0.1"/>
      </geometry>
    </visual>
    <collision>
      <origin rpy="0 -0 0" xyz="0 0 0"/>
      <geometry>
        <mesh filename="package://nao_meshes/meshes/V40/RFinger13_0.10.stl" scale="0.1 0.1 0.1"/>
      </geometry>
    </collision>
    <inertial>
      <mass value="0.2e-5"/>
      <origin xyz="0 0 0"/>
      <inertia ixx="1e-9" ixy="0" ixz="0" iyy="1e-9" iyz="0" izz="1e-9"/>
    </inertial>
  </link>
  <joint name="RFinger2" type="revolute">
    <parent link="r_wrist"/>
    <child link="RFinger21_link"/>
    <origin rpy="0 0 0" xyz="0.06907 -0.01157 -0.00304"/>
    <axis xyz="0 1 0"/>
    <mimic joint="RHand" multiplier="-0.785398163398" offset="0.785398163398"/>
    <limit effort="10.0" lower="0.0" upper="0.785398163398" velocity="3.0"/>
    <dynamics damping="0.1" friction="0" />
  </joint>

  <gazebo reference="RFinger2">
    <implicitSpringDamper>1</implicitSpringDamper>
  </gazebo>

  <link name="RFinger21_link">
    <visual>
      <origin rpy="0 -0 0" xyz="0 0 0"/>
      <geometry>
        <mesh filename="package://nao_meshes/meshes/V40/RFinger21.dae" scale="0.1 0.1 0.1"/>
      </geometry>
    </visual>
    <collision>
      <origin rpy="0 -0 0" xyz="0 0 0"/>
      <geometry>
        <mesh filename="package://nao_meshes/meshes/V40/RFinger21_0.10.stl" scale="0.1 0.1 0.1"/>
      </geometry>
    </collision>
    <inertial>
      <mass value="0.2e-5"/>
      <origin xyz="0 0 0"/>
      <inertia ixx="1e-9" ixy="0" ixz="0" iyy="1e-9" iyz="0" izz="1e-9"/>
    </inertial>
  </link>
  <joint name="RFinger21" type="revolute">
    <parent link="RFinger21_link"/>
    <child link="RFinger22_link"/>
    <origin rpy="0 0 0" xyz="0.01436 0 0"/>
    <axis xyz="0 1 0"/>
    <mimic joint="RHand" multiplier="-0.785398163398" offset="0.785398163398"/>
    <limit effort="10.0" lower="0.0" upper="0.785398163398" velocity="3.0"/>
    <dynamics damping="0.1" friction="0" />
  </joint>

  <gazebo reference="RFinger21">
    <implicitSpringDamper>1</implicitSpringDamper>
  </gazebo>

  <link name="RFinger22_link">
    <visual>
      <origin rpy="0 -0 0" xyz="0 0 0"/>
      <geometry>
        <mesh filename="package://nao_meshes/meshes/V40/RFinger22.dae" scale="0.1 0.1 0.1"/>
      </geometry>
    </visual>
    <collision>
      <origin rpy="0 -0 0" xyz="0 0 0"/>
      <geometry>
        <mesh filename="package://nao_meshes/meshes/V40/RFinger22_0.10.stl" scale="0.1 0.1 0.1"/>
      </geometry>
    </collision>
    <inertial>
      <mass value="0.2e-5"/>
      <origin xyz="0 0 0"/>
      <inertia ixx="1e-9" ixy="0" ixz="0" iyy="1e-9" iyz="0" izz="1e-9"/>
    </inertial>
  </link>
  <joint name="RFinger22" type="revolute">
    <parent link="RFinger22_link"/>
    <child link="RFinger23_link"/>
    <origin rpy="0 0 0" xyz="0.01436 0 0"/>
    <axis xyz="0 1 0"/>
    <mimic joint="RHand" multiplier="-0.785398163398" offset="0.785398163398"/>
    <limit effort="10.0" lower="0.0" upper="0.785398163398" velocity="3.0"/>
    <dynamics damping="0.1" friction="0" />
  </joint>

  <gazebo reference="RFinger22">
    <implicitSpringDamper>1</implicitSpringDamper>
  </gazebo>

  <link name="RFinger23_link">
    <visual>
      <origin rpy="0 -0 0" xyz="0 0 0"/>
      <geometry>
        <mesh filename="package://nao_meshes/meshes/V40/RFinger23.dae" scale="0.1 0.1 0.1"/>
      </geometry>
    </visual>
    <collision>
      <origin rpy="0 -0 0" xyz="0 0 0"/>
      <geometry>
        <mesh filename="package://nao_meshes/meshes/V40/RFinger23_0.10.stl" scale="0.1 0.1 0.1"/>
      </geometry>
    </collision>
    <inertial>
      <mass value="0.2e-5"/>
      <origin xyz="0 0 0"/>
      <inertia ixx="1e-9" ixy="0" ixz="0" iyy="1e-9" iyz="0" izz="1e-9"/>
    </inertial>
  </link>
  <joint name="LThumb1" type="revolute">
    <parent link="l_wrist"/>
    <child link="LThumb1_link"/>
    <origin rpy="3.14159265359 0.785398163398 0" xyz="0.04895 0 -0.02638"/>
    <axis xyz="0 1 0"/>
    <mimic joint="LHand" multiplier="-0.785398163398" offset="0.785398163398"/>
    <limit effort="10.0" lower="0.0" upper="0.785398163398" velocity="3.0"/>
    <dynamics damping="0.1" friction="0" />
  </joint>

  <gazebo reference="LThumb1">
    <implicitSpringDamper>1</implicitSpringDamper>
  </gazebo>

  <link name="LThumb1_link">
    <visual>
      <origin rpy="0 -0 0" xyz="0 0 0"/>
      <geometry>
        <mesh filename="package://nao_meshes/meshes/V40/LThumb1.dae" scale="0.1 0.1 0.1"/>
      </geometry>
    </visual>
    <collision>
      <origin rpy="0 -0 0" xyz="0 0 0"/>
      <geometry>
        <mesh filename="package://nao_meshes/meshes/V40/LThumb1_0.10.stl" scale="0.1 0.1 0.1"/>
      </geometry>
    </collision>
    <inertial>
      <mass value="0.2e-5"/>
      <origin xyz="0 0 0"/>
      <inertia ixx="1e-9" ixy="0" ixz="0" iyy="1e-9" iyz="0" izz="1e-9"/>
    </inertial>
  </link>
  <joint name="LThumb12" type="revolute">
    <parent link="LThumb1_link"/>
    <child link="LThumb2_link"/>
    <origin rpy="0 0 0" xyz="0.01436 0 0"/>
    <axis xyz="0 1 0"/>
    <mimic joint="LHand" multiplier="-0.785398163398" offset="0.785398163398"/>
    <limit effort="10.0" lower="0.0" upper="0.785398163398" velocity="3.0"/>
    <dynamics damping="0.1" friction="0" />
  </joint>

  <gazebo reference="LThumb12">
    <implicitSpringDamper>1</implicitSpringDamper>
  </gazebo>

  <link name="LThumb2_link">
    <visual>
      <origin rpy="0 -0 0" xyz="0 0 0"/>
      <geometry>
        <mesh filename="package://nao_meshes/meshes/V40/LThumb2.dae" scale="0.1 0.1 0.1"/>
      </geometry>
    </visual>
    <collision>
      <origin rpy="0 -0 0" xyz="0 0 0"/>
      <geometry>
        <mesh filename="package://nao_meshes/meshes/V40/LThumb2_0.10.stl" scale="0.1 0.1 0.1"/>
      </geometry>
    </collision>
    <inertial>
      <mass value="0.2e-5"/>
      <origin xyz="0 0 0"/>
      <inertia ixx="1e-9" ixy="0" ixz="0" iyy="1e-9" iyz="0" izz="1e-9"/>
    </inertial>
  </link>
  <joint name="RThumb1" type="revolute">
    <parent link="r_wrist"/>
    <child link="RThumb1_link"/>
    <origin rpy="3.14159265359 0.785398163398 0" xyz="0.04895 0 -0.02638"/>
    <axis xyz="0 1 0"/>
    <mimic joint="RHand" multiplier="-0.785398163398" offset="0.785398163398"/>
    <limit effort="10.0" lower="0.0" upper="0.785398163398" velocity="3.0"/>
    <dynamics damping="0.1" friction="0" />
  </joint>

  <gazebo reference="RThumb1">
    <implicitSpringDamper>1</implicitSpringDamper>
  </gazebo>

  <link name="RThumb1_link">
    <visual>
      <origin rpy="0 -0 0" xyz="0 0 0"/>
      <geometry>
        <mesh filename="package://nao_meshes/meshes/V40/RThumb1.dae" scale="0.1 0.1 0.1"/>
      </geometry>
    </visual>
    <collision>
      <origin rpy="0 -0 0" xyz="0 0 0"/>
      <geometry>
        <mesh filename="package://nao_meshes/meshes/V40/RThumb1_0.10.stl" scale="0.1 0.1 0.1"/>
      </geometry>
    </collision>
    <inertial>
      <mass value="0.2e-5"/>
      <origin xyz="0 0 0"/>
      <inertia ixx="1e-9" ixy="0" ixz="0" iyy="1e-9" iyz="0" izz="1e-9"/>
    </inertial>
  </link>
  <joint name="RThumb12" type="revolute">
    <parent link="RThumb1_link"/>
    <child link="RThumb2_link"/>
    <origin rpy="0 0 0" xyz="0.01436 0 0"/>
    <axis xyz="0 1 0"/>
    <mimic joint="RHand" multiplier="-0.785398163398" offset="0.785398163398"/>
    <limit effort="10.0" lower="0.0" upper="0.785398163398" velocity="3.0"/>
    <dynamics damping="0.1" friction="0" />
  </joint>

  <gazebo reference="RThumb12">
    <implicitSpringDamper>1</implicitSpringDamper>
  </gazebo>

  <link name="RThumb2_link">
    <visual>
      <origin rpy="0 -0 0" xyz="0 0 0"/>
      <geometry>
        <mesh filename="package://nao_meshes/meshes/V40/RThumb2.dae" scale="0.1 0.1 0.1"/>
      </geometry>
    </visual>
    <collision>
      <origin rpy="0 -0 0" xyz="0 0 0"/>
      <geometry>
        <mesh filename="package://nao_meshes/meshes/V40/RThumb2_0.10.stl" scale="0.1 0.1 0.1"/>
      </geometry>
    </collision>
    <inertial>
      <mass value="0.2e-5"/>
      <origin xyz="0 0 0"/>
      <inertia ixx="1e-9" ixy="0" ixz="0" iyy="1e-9" iyz="0" izz="1e-9"/>
    </inertial>
  </link>
  <joint name="HeadYaw" type="revolute">
    <parent link="torso"/>
    <child link="Neck"/>
    <origin rpy="0 0 0" xyz="0 0 0.1265"/>
    <axis xyz="0 0 1.0"/>
    <limit effort="1.2" lower="-2.08567" upper="2.08567" velocity="8.26797"/>
    <dynamics damping="0.1" friction="0" />
  </joint>

  <gazebo reference="HeadYaw">
    <implicitSpringDamper>1</implicitSpringDamper>
  </gazebo>

  <link name="Neck">
    <inertial>
      <mass value="0.06442"/>
      <inertia ixx="7.4993e-05" ixy="1.57e-09" ixz="-1.834e-08" iyy="7.6e-05" iyz="-5.295e-08" izz="5.53373e-06"/>
      <origin rpy="0 0 0" xyz="-1e-05 0 -0.02742"/>
    </inertial>
    <visual>
      <geometry>
        <mesh filename="package://nao_meshes/meshes/V40/HeadYaw.dae" scale="0.1 0.1 0.1"/>
      </geometry>
    </visual>
    <collision>
      <geometry>
        <mesh filename="package://nao_meshes/meshes/V40/HeadYaw_0.10.stl" scale="0.1 0.1 0.1"/>
      </geometry>
    </collision>
  </link>
  <joint name="HeadPitch" type="revolute">
    <parent link="Neck"/>
    <child link="Head"/>
    <origin rpy="0 0 0" xyz="0 0 0"/>
    <axis xyz="0 1.0 0"/>
    <limit effort="1.2" lower="-0.671952" upper="0.514872" velocity="7.19407"/>
    <dynamics damping="0.1" friction="0" />
  </joint>

  <gazebo reference="HeadPitch">
    <implicitSpringDamper>1</implicitSpringDamper>
  </gazebo>

  <link name="Head">
    <inertial>
      <mass value="0.60533"/>
      <inertia ixx="0.0026313" ixy="8.78814e-06" ixz="4.09847e-05" iyy="0.00249112" iyz="-2.99579e-05" izz="0.000985736"/>
      <origin rpy="0 0 0" xyz="-0.00112 0 0.05258"/>
    </inertial>
    <visual>
      <geometry>
        <mesh filename="package://nao_meshes/meshes/V40/HeadPitch.dae" scale="0.1 0.1 0.1"/>
      </geometry>
    </visual>
    <collision>
      <geometry>
        <mesh filename="package://nao_meshes/meshes/V40/HeadPitch_0.10.stl" scale="0.1 0.1 0.1"/>
      </geometry>
    </collision>
  </link>
  <joint name="gaze_joint" type="fixed">
    <parent link="Head"/>
    <child link="gaze"/>
    <origin rpy="0 0.0209 0" xyz="0.05871 0 0.06364"/>
    <dynamics damping="0.1" friction="0" />
  </joint>

  <gazebo reference="gaze_joint">
    <implicitSpringDamper>1</implicitSpringDamper>
  </gazebo>

  <link name="gaze"/>
  <joint name="LHipYawPitch" type="revolute">
    <parent link="torso"/>
    <child link="LPelvis"/>
    <origin rpy="0 0 0" xyz="0 0.05 -0.085"/>
    <axis xyz="0 0.707106 -0.707106"/>
    <limit effort="3.2" lower="-1.14529" upper="0.740718" velocity="4.16174"/>
    <dynamics damping="0.1" friction="0" />
  </joint>

  <gazebo reference="LHipYawPitch">
    <implicitSpringDamper>1</implicitSpringDamper>
  </gazebo>

  <link name="LPelvis">
    <inertial>
      <mass value="0.06981"/>
      <inertia ixx="8.15023e-05" ixy="-4.99449e-06" ixz="1.27482e-05" iyy="0.000101326" iyz="2.34547e-05" izz="6.26236e-05"/>
      <origin rpy="0 0 0" xyz="-0.00781 -0.01114 0.02661"/>
    </inertial>
    <visual>
      <geometry>
        <mesh filename="package://nao_meshes/meshes/V40/LHipYawPitch.dae" scale="0.1 0.1 0.1"/>
      </geometry>
    </visual>
    <collision>
      <geometry>
        <mesh filename="package://nao_meshes/meshes/V40/LHipYawPitch_0.10.stl" scale="0.1 0.1 0.1"/>
      </geometry>
    </collision>
  </link>
  <joint name="LHipRoll" type="revolute">
    <parent link="LPelvis"/>
    <child link="LHip"/>
    <origin rpy="0 0 0" xyz="0 0 0"/>
    <axis xyz="1.0 0 0"/>
    <limit effort="3.2" lower="-0.379435" upper="0.79046" velocity="4.16174"/>
    <dynamics damping="0.1" friction="0" />
  </joint>

  <gazebo reference="LHipRoll">
    <implicitSpringDamper>1</implicitSpringDamper>
  </gazebo>

  <link name="LHip">
    <inertial>
      <mass value="0.13053"/>
      <inertia ixx="2.75835e-05" ixy="-2.233e-08" ixz="-4.08164e-06" iyy="9.82706e-05" iyz="-4.19e-09" izz="8.80997e-05"/>
      <origin rpy="0 0 0" xyz="-0.01549 0.00029 -0.00515"/>
    </inertial>
    <visual>
      <geometry>
        <mesh filename="package://nao_meshes/meshes/V40/LHipRoll.dae" scale="0.1 0.1 0.1"/>
      </geometry>
    </visual>
    <collision>
      <geometry>
        <mesh filename="package://nao_meshes/meshes/V40/LHipRoll_0.10.stl" scale="0.1 0.1 0.1"/>
      </geometry>
    </collision>
  </link>
  <joint name="LHipPitch" type="revolute">
    <parent link="LHip"/>
    <child link="LThigh"/>
    <origin rpy="0 0 0" xyz="0 0 0"/>
    <axis xyz="0 1.0 0"/>
    <limit effort="3.2" lower="-1.53589" upper="0.48398" velocity="6.40239"/>
    <dynamics damping="0.1" friction="0" />
  </joint>

  <gazebo reference="LHipPitch">
    <implicitSpringDamper>1</implicitSpringDamper>
  </gazebo>

  <link name="LThigh">
    <inertial>
      <mass value="0.38968"/>
      <inertia ixx="0.00163672" ixy="9.2451e-07" ixz="8.53067e-05" iyy="0.00159107" iyz="3.83616e-05" izz="0.000303743"/>
      <origin rpy="0 0 0" xyz="0.00138 0.00221 -0.05373"/>
    </inertial>
    <visual>
      <geometry>
        <mesh filename="package://nao_meshes/meshes/V40/LHipPitch.dae" scale="0.1 0.1 0.1"/>
      </geometry>
    </visual>
    <collision>
      <geometry>
        <mesh filename="package://nao_meshes/meshes/V40/LHipPitch_0.10.stl" scale="0.1 0.1 0.1"/>
      </geometry>
    </collision>
  </link>
  <joint name="LKneePitch" type="revolute">
    <parent link="LThigh"/>
    <child link="LTibia"/>
    <origin rpy="0 0 0" xyz="0 0 -0.1"/>
    <axis xyz="0 1.0 0"/>
    <limit effort="3.2" lower="-0.0923279" upper="2.11255" velocity="6.40239"/>
    <dynamics damping="0.1" friction="0" />
  </joint>

  <gazebo reference="LKneePitch">
    <implicitSpringDamper>1</implicitSpringDamper>
  </gazebo>

  <link name="LTibia">
    <inertial>
      <mass value="0.29142"/>
      <inertia ixx="0.00118208" ixy="6.3362e-07" ixz="3.6497e-05" iyy="0.00112865" iyz="3.94952e-05" izz="0.000193227"/>
      <origin rpy="0 0 0" xyz="0.00453 0.00225 -0.04936"/>
    </inertial>
    <visual>
      <geometry>
        <mesh filename="package://nao_meshes/meshes/V40/LKneePitch.dae" scale="0.1 0.1 0.1"/>
      </geometry>
    </visual>
    <collision>
      <geometry>
        <mesh filename="package://nao_meshes/meshes/V40/LKneePitch_0.10.stl" scale="0.1 0.1 0.1"/>
      </geometry>
    </collision>
  </link>
  <joint name="LAnklePitch" type="revolute">
    <parent link="LTibia"/>
    <child link="l_ankle"/>
    <origin rpy="0 0 0" xyz="0 0 -0.1029"/>
    <axis xyz="0 1.0 0"/>
    <limit effort="3.2" lower="-1.18944" upper="0.922581" velocity="6.40239"/>
    <dynamics damping="0.1" friction="0" />
  </joint>

  <gazebo reference="LAnklePitch">
    <implicitSpringDamper>1</implicitSpringDamper>
  </gazebo>

  <link name="l_ankle">
    <inertial>
      <mass value="0.13416"/>
      <inertia ixx="3.85098e-05" ixy="-2.634e-08" ixz="3.86194e-06" iyy="7.42653e-05" iyz="1.834e-08" izz="5.48654e-05"/>
      <origin rpy="0 0 0" xyz="0.00045 0.00029 0.00685"/>
    </inertial>
    <visual>
      <geometry>
        <mesh filename="package://nao_meshes/meshes/V40/LAnklePitch.dae" scale="0.1 0.1 0.1"/>
      </geometry>
    </visual>
    <collision>
      <geometry>
        <mesh filename="package://nao_meshes/meshes/V40/LAnklePitch_0.10.stl" scale="0.1 0.1 0.1"/>
      </geometry>
    </collision>
  </link>
  <joint name="LAnkleRoll" type="revolute">
    <parent link="l_ankle"/>
    <child link="l_sole"/>
    <origin rpy="0 0 0" xyz="0 0 0"/>
    <axis xyz="1.0 0 0"/>
    <limit effort="3.2" lower="-0.397761" upper="0.768992" velocity="4.16174"/>
    <dynamics damping="0.1" friction="0" />
  </joint>

  <gazebo reference="LAnkleRoll">
    <implicitSpringDamper>1</implicitSpringDamper>
  </gazebo>

  <link name="l_sole">
    <inertial>
      <mass value="0.16184"/>
      <inertia ixx="0.000269442" ixy="-5.69572e-06" ixz="0.000139379" iyy="0.000644343" iyz="1.87409e-05" izz="0.000525757"/>
      <origin rpy="0 0 0" xyz="0.02542 0.0033 -0.03239"/>
    </inertial>
    <visual>
      <geometry>
        <mesh filename="package://nao_meshes/meshes/V40/LAnkleRoll.dae" scale="0.1 0.1 0.1"/>
      </geometry>
    </visual>
    <collision>
      <geometry>
        <mesh filename="package://nao_meshes/meshes/V40/LAnkleRoll_0.10.stl" scale="0.1 0.1 0.1"/>
      </geometry>
    </collision>
  </link>
  <joint name="RHipYawPitch" type="revolute">
    <parent link="torso"/>
    <child link="RPelvis"/>
    <origin rpy="0 0 0" xyz="0 -0.05 -0.085"/>
    <axis xyz="0 0.707106 0.707106"/>
    <limit effort="3.2" lower="-1.14529" upper="0.740718" velocity="4.16174"/>
    <dynamics damping="0.1" friction="0" />
  </joint>

  <gazebo reference="RHipYawPitch">
    <implicitSpringDamper>1</implicitSpringDamper>
  </gazebo>

  <link name="RPelvis">
    <inertial>
      <mass value="0.06981"/>
      <inertia ixx="8.9972e-05" ixy="5.00219e-06" ixz="1.27352e-05" iyy="0.000105526" iyz="-2.77008e-05" izz="6.68872e-05"/>
      <origin rpy="0 0 0" xyz="-0.00781 0.01114 0.02661"/>
    </inertial>
    <visual>
      <geometry>
        <mesh filename="package://nao_meshes/meshes/V40/RHipYawPitch.dae" scale="0.1 0.1 0.1"/>
      </geometry>
    </visual>
    <collision>
      <geometry>
        <mesh filename="package://nao_meshes/meshes/V40/RHipYawPitch_0.10.stl" scale="0.1 0.1 0.1"/>
      </geometry>
    </collision>
  </link>
  <joint name="RHipRoll" type="revolute">
    <parent link="RPelvis"/>
    <child link="RHip"/>
    <origin rpy="0 0 0" xyz="0 0 0"/>
    <axis xyz="1.0 0 0"/>
    <limit effort="3.2" lower="-0.79046" upper="0.379435" velocity="4.16174"/>
    <dynamics damping="0.1" friction="0" />
  </joint>

  <gazebo reference="RHipRoll">
    <implicitSpringDamper>1</implicitSpringDamper>
  </gazebo>

  <link name="RHip">
    <inertial>
      <mass value="0.13053"/>
      <inertia ixx="2.75865e-05" ixy="-1.919e-08" ixz="-4.10822e-06" iyy="9.827e-05" iyz="2.51e-09" izz="8.81033e-05"/>
      <origin rpy="0 0 0" xyz="-0.01549 -0.00029 -0.00515"/>
    </inertial>
    <visual>
      <geometry>
        <mesh filename="package://nao_meshes/meshes/V40/RHipRoll.dae" scale="0.1 0.1 0.1"/>
      </geometry>
    </visual>
    <collision>
      <geometry>
        <mesh filename="package://nao_meshes/meshes/V40/RHipRoll_0.10.stl" scale="0.1 0.1 0.1"/>
      </geometry>
    </collision>
  </link>
  <joint name="RHipPitch" type="revolute">
    <parent link="RHip"/>
    <child link="RThigh"/>
    <origin rpy="0 0 0" xyz="0 0 0"/>
    <axis xyz="0 1.0 0"/>
    <limit effort="3.2" lower="-1.53589" upper="0.48398" velocity="6.40239"/>
    <dynamics damping="0.1" friction="0" />
  </joint>

  <gazebo reference="RHipPitch">
    <implicitSpringDamper>1</implicitSpringDamper>
  </gazebo>

  <link name="RThigh">
    <inertial>
      <mass value="0.38968"/>
      <inertia ixx="0.00163748" ixy="-8.3954e-07" ixz="8.5883e-05" iyy="0.00159221" iyz="-3.91763e-05" izz="0.000303978"/>
      <origin rpy="0 0 0" xyz="0.00138 -0.00221 -0.05373"/>
    </inertial>
    <visual>
      <geometry>
        <mesh filename="package://nao_meshes/meshes/V40/RHipPitch.dae" scale="0.1 0.1 0.1"/>
      </geometry>
    </visual>
    <collision>
      <geometry>
        <mesh filename="package://nao_meshes/meshes/V40/RHipPitch_0.10.stl" scale="0.1 0.1 0.1"/>
      </geometry>
    </collision>
  </link>
  <joint name="RKneePitch" type="revolute">
    <parent link="RThigh"/>
    <child link="RTibia"/>
    <origin rpy="0 0 0" xyz="0 0 -0.1"/>
    <axis xyz="0 1.0 0"/>
    <limit effort="3.2" lower="-0.0923279" upper="2.11255" velocity="6.40239"/>
    <dynamics damping="0.1" friction="0" />
  </joint>

  <gazebo reference="RKneePitch">
    <implicitSpringDamper>1</implicitSpringDamper>
  </gazebo>

  <link name="RTibia">
    <inertial>
      <mass value="0.29142"/>
      <inertia ixx="0.00118283" ixy="-8.965e-07" ixz="2.79969e-05" iyy="0.00112828" iyz="-3.8476e-05" izz="0.000191453"/>
      <origin rpy="0 0 0" xyz="0.00453 -0.00225 -0.04936"/>
    </inertial>
    <visual>
      <geometry>
        <mesh filename="package://nao_meshes/meshes/V40/RKneePitch.dae" scale="0.1 0.1 0.1"/>
      </geometry>
    </visual>
    <collision>
      <geometry>
        <mesh filename="package://nao_meshes/meshes/V40/RKneePitch_0.10.stl" scale="0.1 0.1 0.1"/>
      </geometry>
    </collision>
  </link>
  <joint name="RAnklePitch" type="revolute">
    <parent link="RTibia"/>
    <child link="r_ankle"/>
    <origin rpy="0 0 0" xyz="0 0 -0.1029"/>
    <axis xyz="0 1.0 0"/>
    <limit effort="3.2" lower="-1.1863" upper="0.932006" velocity="6.40239"/>
    <dynamics damping="0.1" friction="0" />
  </joint>

  <gazebo reference="RAnklePitch">
    <implicitSpringDamper>1</implicitSpringDamper>
  </gazebo>

  <link name="r_ankle">
    <inertial>
      <mass value="0.13416"/>
      <inertia ixx="3.85081e-05" ixy="6.434e-08" ixz="3.87466e-06" iyy="7.43108e-05" iyz="-4.58e-09" izz="5.49131e-05"/>
      <origin rpy="0 0 0" xyz="0.00045 -0.00029 0.00685"/>
    </inertial>
    <visual>
      <geometry>
        <mesh filename="package://nao_meshes/meshes/V40/RAnklePitch.dae" scale="0.1 0.1 0.1"/>
      </geometry>
    </visual>
    <collision>
      <geometry>
        <mesh filename="package://nao_meshes/meshes/V40/RAnklePitch_0.10.stl" scale="0.1 0.1 0.1"/>
      </geometry>
    </collision>
  </link>
  <joint name="RAnkleRoll" type="revolute">
    <parent link="r_ankle"/>
    <child link="r_sole"/>
    <origin rpy="0 0 0" xyz="0 0 0"/>
    <axis xyz="1.0 0 0"/>
    <limit effort="3.2" lower="-0.768992" upper="0.397935" velocity="4.16174"/>
    <dynamics damping="0.1" friction="0" />
  </joint>

  <gazebo reference="RAnkleRoll">
    <implicitSpringDamper>1</implicitSpringDamper>
  </gazebo>

  <link name="r_sole">
    <inertial>
      <mass value="0.16184"/>
      <inertia ixx="0.000269302" ixy="5.87505e-06" ixz="0.000139133" iyy="0.000643474" iyz="-1.88492e-05" izz="0.000525035"/>
      <origin rpy="0 0 0" xyz="0.02542 -0.0033 -0.03239"/>
    </inertial>
    <visual>
      <geometry>
        <mesh filename="package://nao_meshes/meshes/V40/RAnkleRoll.dae" scale="0.1 0.1 0.1"/>
      </geometry>
    </visual>
    <collision>
      <geometry>
        <mesh filename="package://nao_meshes/meshes/V40/RAnkleRoll_0.10.stl" scale="0.1 0.1 0.1"/>
      </geometry>
    </collision>
  </link>
  <link name="base_link"/>
  <joint name="base_joint" type="fixed">
    <parent link="base_link"/>
    <child link="torso"/>
    <origin rpy="0 0 0" xyz="0 0 0"/>
    <dynamics damping="0.1" friction="0" />
  </joint>

  <gazebo reference="base_joint">
    <implicitSpringDamper>1</implicitSpringDamper>
  </gazebo>

  <link name="torso">
    <inertial>
      <mass value="1.04956"/>
      <inertia ixx="0.00506234" ixy="1.43116e-05" ixz="0.000155191" iyy="0.00488014" iyz="-2.70793e-05" izz="0.0016103"/>
      <origin rpy="0 0 0" xyz="-0.00413 0 0.04342"/>
    </inertial>
    <visual>
      <geometry>
        <mesh filename="package://nao_meshes/meshes/V40/Torso.dae" scale="0.1 0.1 0.1"/>
      </geometry>
    </visual>
    <collision>
      <geometry>
        <mesh filename="package://nao_meshes/meshes/V40/Torso_0.10.stl" scale="0.1 0.1 0.1"/>
      </geometry>
    </collision>
  </link>
  <joint name="LShoulderPitch" type="revolute">
    <parent link="torso"/>
    <child link="LShoulder"/>
    <origin rpy="0 0 0" xyz="0 0.098 0.1"/>
    <axis xyz="0 1.0 0"/>
    <limit effort="1.2" lower="-2.08567" upper="2.08567" velocity="8.26797"/>
    <dynamics damping="0.1" friction="0" />
  </joint>

  <gazebo reference="LShoulderPitch">
    <implicitSpringDamper>1</implicitSpringDamper>
  </gazebo>

  <link name="LShoulder">
    <inertial>
      <mass value="0.07504"/>
      <inertia ixx="8.42843e-05" ixy="-2.02802e-06" ixz="2.338e-08" iyy="1.41556e-05" iyz="-1.972e-08" izz="8.64195e-05"/>
      <origin rpy="0 0 0" xyz="-0.00165 -0.02663 0.00014"/>
    </inertial>
    <visual>
      <geometry>
        <mesh filename="package://nao_meshes/meshes/V40/LShoulderPitch.dae" scale="0.1 0.1 0.1"/>
      </geometry>
    </visual>
    <collision>
      <geometry>
        <mesh filename="package://nao_meshes/meshes/V40/LShoulderPitch_0.10.stl" scale="0.1 0.1 0.1"/>
      </geometry>
    </collision>
  </link>
  <joint name="LShoulderRoll" type="revolute">
    <parent link="LShoulder"/>
    <child link="LBicep"/>
    <origin rpy="0 0 0" xyz="0 0 0"/>
    <axis xyz="0 0 1.0"/>
    <limit effort="1.2" lower="-0.314159" upper="1.32645" velocity="7.19407"/>
    <dynamics damping="0.1" friction="0" />
  </joint>

  <gazebo reference="LShoulderRoll">
    <implicitSpringDamper>1</implicitSpringDamper>
  </gazebo>

  <link name="LBicep">
    <inertial>
      <mass value="0.15777"/>
      <inertia ixx="9.38999e-05" ixy="-4.71445e-05" ixz="-2.69947e-05" iyy="0.000371519" iyz="-2.45977e-06" izz="0.000341901"/>
      <origin rpy="0 0 0" xyz="0.02455 0.00563 0.0033"/>
    </inertial>
    <visual>
      <geometry>
        <mesh filename="package://nao_meshes/meshes/V40/LShoulderRoll.dae" scale="0.1 0.1 0.1"/>
      </geometry>
    </visual>
    <collision>
      <geometry>
        <mesh filename="package://nao_meshes/meshes/V40/LShoulderRoll_0.10.stl" scale="0.1 0.1 0.1"/>
      </geometry>
    </collision>
  </link>
  <joint name="LElbowYaw" type="revolute">
    <parent link="LBicep"/>
    <child link="LElbow"/>
    <origin rpy="0 0 0" xyz="0.105 0.015 0"/>
    <axis xyz="1.0 0 0"/>
    <limit effort="1.2" lower="-2.08567" upper="2.08567" velocity="8.26797"/>
    <dynamics damping="0.1" friction="0" />
  </joint>

  <gazebo reference="LElbowYaw">
    <implicitSpringDamper>1</implicitSpringDamper>
  </gazebo>

  <link name="LElbow">
    <inertial>
      <mass value="0.06483"/>
      <inertia ixx="5.59715e-06" ixy="4.21e-09" ixz="4.319e-08" iyy="7.54331e-05" iyz="-1.84e-09" izz="7.64434e-05"/>
      <origin rpy="0 0 0" xyz="-0.02744 0 -0.00014"/>
    </inertial>
  </link>
  <joint name="LElbowRoll" type="revolute">
    <parent link="LElbow"/>
    <child link="LForeArm"/>
    <origin rpy="0 0 0" xyz="0 0 0"/>
    <axis xyz="0 0 1.0"/>
    <limit effort="1.2" lower="-1.54462" upper="-0.0349066" velocity="7.19407"/>
    <dynamics damping="0.1" friction="0" />
  </joint>

  <gazebo reference="LElbowRoll">
    <implicitSpringDamper>1</implicitSpringDamper>
  </gazebo>

  <link name="LForeArm">
    <inertial>
      <mass value="0.07761"/>
      <inertia ixx="2.53322e-05" ixy="-2.34271e-06" ixz="7.459e-08" iyy="8.91322e-05" iyz="-2.655e-08" izz="8.72873e-05"/>
      <origin rpy="0 0 0" xyz="0.02556 0.00281 0.00076"/>
    </inertial>
    <visual>
      <geometry>
        <mesh filename="package://nao_meshes/meshes/V40/LElbowRoll.dae" scale="0.1 0.1 0.1"/>
      </geometry>
    </visual>
    <collision>
      <geometry>
        <mesh filename="package://nao_meshes/meshes/V40/LElbowRoll_0.10.stl" scale="0.1 0.1 0.1"/>
      </geometry>
    </collision>
  </link>
  <joint name="LWristYaw" type="revolute">
    <parent link="LForeArm"/>
    <child link="l_wrist"/>
    <origin rpy="0 0 0" xyz="0.05595 0 0"/>
    <axis xyz="1.0 0 0"/>
    <limit effort="0.76" lower="-1.82387" upper="1.82387" velocity="24.6229"/>
    <dynamics damping="0.1" friction="0" />
  </joint>

  <gazebo reference="LWristYaw">
    <implicitSpringDamper>1</implicitSpringDamper>
  </gazebo>

  <link name="l_wrist">
    <inertial>
      <mass value="0.18533"/>
      <inertia ixx="7.05493e-05" ixy="5.71599e-06" ixz="-2.24744e-05" iyy="0.000356062" iyz="3.17771e-06" izz="0.000351919"/>
      <origin rpy="0 0 0" xyz="0.03434 -0.00088 0.00308"/>
    </inertial>
    <visual>
      <geometry>
        <mesh filename="package://nao_meshes/meshes/V40/LWristYaw.dae" scale="0.1 0.1 0.1"/>
      </geometry>
    </visual>
    <collision>
      <geometry>
        <mesh filename="package://nao_meshes/meshes/V40/LWristYaw_0.10.stl" scale="0.1 0.1 0.1"/>
      </geometry>
    </collision>
  </link>
  <joint name="LHand" type="revolute">
    <parent link="l_wrist"/>
    <child link="l_gripper"/>
    <origin rpy="0 0 0" xyz="0.05775 0 -0.01231"/>
    <limit effort="0.177576" lower="0" upper="1.0" velocity="3"/>
    <dynamics damping="0.1" friction="0" />
  </joint>

  <gazebo reference="LHand">
    <implicitSpringDamper>1</implicitSpringDamper>
  </gazebo>

  <link name="l_gripper">
    <inertial>
      <mass value="2e-06"/>
      <inertia ixx="1.1e-09" ixy="0" ixz="0" iyy="1.1e-09" iyz="0" izz="1.1e-09"/>
      <origin rpy="0 0 0" xyz="0 0 0"/>
    </inertial>
  </link>
  <joint name="RShoulderPitch" type="revolute">
    <parent link="torso"/>
    <child link="RShoulder"/>
    <origin rpy="0 0 0" xyz="0 -0.098 0.1"/>
    <axis xyz="0 1.0 0"/>
    <limit effort="1.2" lower="-2.08567" upper="2.08567" velocity="8.26797"/>
    <dynamics damping="0.1" friction="0" />
  </joint>

  <gazebo reference="RShoulderPitch">
    <implicitSpringDamper>1</implicitSpringDamper>
  </gazebo>

  <link name="RShoulder">
    <inertial>
      <mass value="0.07504"/>
      <inertia ixx="8.42843e-05" ixy="2.02802e-06" ixz="2.338e-08" iyy="1.41556e-05" iyz="1.972e-08" izz="8.64195e-05"/>
      <origin rpy="0 0 0" xyz="-0.00165 0.02663 0.00014"/>
    </inertial>
    <visual>
      <geometry>
        <mesh filename="package://nao_meshes/meshes/V40/RShoulderPitch.dae" scale="0.1 0.1 0.1"/>
      </geometry>
    </visual>
    <collision>
      <geometry>
        <mesh filename="package://nao_meshes/meshes/V40/RShoulderPitch_0.10.stl" scale="0.1 0.1 0.1"/>
      </geometry>
    </collision>
  </link>
  <joint name="RShoulderRoll" type="revolute">
    <parent link="RShoulder"/>
    <child link="RBicep"/>
    <origin rpy="0 0 0" xyz="0 0 0"/>
    <axis xyz="0 0 1.0"/>
    <limit effort="1.2" lower="-1.32645" upper="0.314159" velocity="7.19407"/>
    <dynamics damping="0.1" friction="0" />
  </joint>

  <gazebo reference="RShoulderRoll">
    <implicitSpringDamper>1</implicitSpringDamper>
  </gazebo>

  <link name="RBicep">
    <inertial>
      <mass value="0.15777"/>
      <inertia ixx="0.00011012" ixy="7.66913e-05" ixz="-2.60461e-05" iyy="0.000367577" iyz="1.20983e-05" izz="0.000354618"/>
      <origin rpy="0 0 0" xyz="0.02455 -0.00563 0.0033"/>
    </inertial>
    <visual>
      <geometry>
        <mesh filename="package://nao_meshes/meshes/V40/RShoulderRoll.dae" scale="0.1 0.1 0.1"/>
      </geometry>
    </visual>
    <collision>
      <geometry>
        <mesh filename="package://nao_meshes/meshes/V40/RShoulderRoll_0.10.stl" scale="0.1 0.1 0.1"/>
      </geometry>
    </collision>
  </link>
  <joint name="RElbowYaw" type="revolute">
    <parent link="RBicep"/>
    <child link="RElbow"/>
    <origin rpy="0 0 0" xyz="0.105 -0.015 0"/>
    <axis xyz="1.0 0 0"/>
    <limit effort="1.2" lower="-2.08567" upper="2.08567" velocity="8.26797"/>
    <dynamics damping="0.1" friction="0" />
  </joint>

  <gazebo reference="RElbowYaw">
    <implicitSpringDamper>1</implicitSpringDamper>
  </gazebo>

  <link name="RElbow">
    <inertial>
      <mass value="0.06483"/>
      <inertia ixx="5.59715e-06" ixy="4.21e-09" ixz="4.319e-08" iyy="7.54331e-05" iyz="-1.84e-09" izz="7.64434e-05"/>
      <origin rpy="0 0 0" xyz="-0.02744 0 -0.00014"/>
    </inertial>
  </link>
  <joint name="RElbowRoll" type="revolute">
    <parent link="RElbow"/>
    <child link="RForeArm"/>
    <origin rpy="0 0 0" xyz="0 0 0"/>
    <axis xyz="0 0 1.0"/>
    <limit effort="1.2" lower="0.0349066" upper="1.54462" velocity="7.19407"/>
    <dynamics damping="0.1" friction="0" />
  </joint>

  <gazebo reference="RElbowRoll">
    <implicitSpringDamper>1</implicitSpringDamper>
  </gazebo>

  <link name="RForeArm">
    <inertial>
      <mass value="0.07761"/>
      <inertia ixx="2.53907e-05" ixy="2.33243e-06" ixz="-6.0117e-07" iyy="8.92204e-05" iyz="2.694e-08" izz="8.72484e-05"/>
      <origin rpy="0 0 0" xyz="0.02556 -0.00281 0.00076"/>
    </inertial>
    <visual>
      <geometry>
        <mesh filename="package://nao_meshes/meshes/V40/RElbowRoll.dae" scale="0.1 0.1 0.1"/>
      </geometry>
    </visual>
    <collision>
      <geometry>
        <mesh filename="package://nao_meshes/meshes/V40/RElbowRoll_0.10.stl" scale="0.1 0.1 0.1"/>
      </geometry>
    </collision>
  </link>
  <joint name="RWristYaw" type="revolute">
    <parent link="RForeArm"/>
    <child link="r_wrist"/>
    <origin rpy="0 0 0" xyz="0.05595 0 0"/>
    <axis xyz="1.0 0 0"/>
    <limit effort="0.76" lower="-1.82387" upper="1.82387" velocity="24.6229"/>
    <dynamics damping="0.1" friction="0" />
  </joint>

  <gazebo reference="RWristYaw">
    <implicitSpringDamper>1</implicitSpringDamper>
  </gazebo>

  <link name="r_wrist">
    <inertial>
      <mass value="0.18533"/>
      <inertia ixx="7.05493e-05" ixy="5.71599e-06" ixz="-2.24744e-05" iyy="0.000356062" iyz="3.17771e-06" izz="0.000351919"/>
      <origin rpy="0 0 0" xyz="0.03434 0.00088 0.00308"/>
    </inertial>
    <visual>
      <geometry>
        <mesh filename="package://nao_meshes/meshes/V40/RWristYaw.dae" scale="0.1 0.1 0.1"/>
      </geometry>
    </visual>
    <collision>
      <geometry>
        <mesh filename="package://nao_meshes/meshes/V40/RWristYaw_0.10.stl" scale="0.1 0.1 0.1"/>
      </geometry>
    </collision>
  </link>
  <joint name="RHand" type="revolute">
    <parent link="r_wrist"/>
    <child link="r_gripper"/>
    <origin rpy="0 0 0" xyz="0.05775 0 -0.01231"/>
    <limit effort="0.177576" lower="0" upper="1.0" velocity="3"/>
    <dynamics damping="0.1" friction="0" />
  </joint>

  <gazebo reference="RHand">
    <implicitSpringDamper>1</implicitSpringDamper>
  </gazebo>

  <link name="r_gripper">
    <inertial>
      <mass value="2e-06"/>
      <inertia ixx="1.1e-09" ixy="0" ixz="0" iyy="1.1e-09" iyz="0" izz="1.1e-09"/>
      <origin rpy="0 0 0" xyz="0 0 0"/>
    </inertial>
  </link>
  <link name="RHandTouchBack_frame"/>
  <joint name="RHandTouchBack_joint" type="fixed">
    <parent link="r_wrist"/>
    <child link="RHandTouchBack_frame"/>
    <origin rpy="0 -1.57079632679 0" xyz="0.038 0 0.025"/>
    <dynamics damping="0.1" friction="0" />
  </joint>

  <gazebo reference="RHandTouchBack_joint">
    <implicitSpringDamper>1</implicitSpringDamper>
  </gazebo>

  <link name="RFsrFL_frame"/>
  <joint name="RFsrFL_joint" type="fixed">
    <parent link="r_ankle"/>
    <child link="RFsrFL_frame"/>
    <origin rpy="0 0 0" xyz="0.07025 0.0231 0"/>
    <dynamics damping="0.1" friction="0" />
  </joint>

  <gazebo reference="RFsrFL_joint">
    <implicitSpringDamper>1</implicitSpringDamper>
  </gazebo>

  <link name="RFsrRL_frame"/>
  <joint name="RFsrRL_joint" type="fixed">
    <parent link="r_ankle"/>
    <child link="RFsrRL_frame"/>
    <origin rpy="0 0 0" xyz="-0.03025 0.0191 0"/>
    <dynamics damping="0.1" friction="0" />
  </joint>

  <gazebo reference="RFsrRL_joint">
    <implicitSpringDamper>1</implicitSpringDamper>
  </gazebo>

  <link name="LSonar_frame"/>
  <joint name="LSonar_joint" type="fixed">
    <parent link="torso"/>
    <child link="LSonar_frame"/>
    <origin rpy="0 0.04365 0.39265" xyz="0.0507 0.03785 0.06035"/>
    <dynamics damping="0.1" friction="0" />
  </joint>

  <gazebo reference="LSonar_joint">
    <implicitSpringDamper>1</implicitSpringDamper>
  </gazebo>

  <link name="LFsrFR_frame"/>
  <joint name="LFsrFR_joint" type="fixed">
    <parent link="l_ankle"/>
    <child link="LFsrFR_frame"/>
    <origin rpy="0 0 0" xyz="0.07025 -0.0231 0"/>
    <dynamics damping="0.1" friction="0" />
  </joint>

  <gazebo reference="LFsrFR_joint">
    <implicitSpringDamper>1</implicitSpringDamper>
  </gazebo>

  <link name="HeadTouchRear_frame"/>
  <joint name="HeadTouchRear_joint" type="fixed">
    <parent link="Head"/>
    <child link="HeadTouchRear_frame"/>
    <origin rpy="3.14159265359 -1.333192995 3.14159265359" xyz="-0.0257 0 0.1045"/>
    <dynamics damping="0.1" friction="0" />
  </joint>

  <gazebo reference="HeadTouchRear_joint">
    <implicitSpringDamper>1</implicitSpringDamper>
  </gazebo>

  <link name="ImuAccelerometer_frame"/>
  <joint name="ImuAccelerometer_joint" type="fixed">
    <parent link="torso"/>
    <child link="ImuAccelerometer_frame"/>
    <origin rpy="0 0 0" xyz="-0.008 0.00606 0.027"/>
    <dynamics damping="0.1" friction="0" />
  </joint>

  <gazebo reference="ImuAccelerometer_joint">
    <implicitSpringDamper>1</implicitSpringDamper>
  </gazebo>

  <link name="HeadTouchMiddle_frame"/>
  <joint name="HeadTouchMiddle_joint" type="fixed">
    <parent link="Head"/>
    <child link="HeadTouchMiddle_frame"/>
    <origin rpy="0 -1.57079632679 0" xyz="0.001 0 0.1099"/>
    <dynamics damping="0.1" friction="0" />
  </joint>

  <gazebo reference="HeadTouchMiddle_joint">
    <implicitSpringDamper>1</implicitSpringDamper>
  </gazebo>

  <link name="ImuGyrometer_frame"/>
  <joint name="ImuGyrometer_joint" type="fixed">
    <parent link="torso"/>
    <child link="ImuGyrometer_frame"/>
    <origin rpy="0 0 0" xyz="-0.008 -0.006 0.029"/>
    <dynamics damping="0.1" friction="0" />
  </joint>

  <gazebo reference="ImuGyrometer_joint">
    <implicitSpringDamper>1</implicitSpringDamper>
  </gazebo>

  <link name="LFsrRL_frame"/>
  <joint name="LFsrRL_joint" type="fixed">
    <parent link="l_ankle"/>
    <child link="LFsrRL_frame"/>
    <origin rpy="0 0 0" xyz="-0.03025 0.0299 0"/>
    <dynamics damping="0.1" friction="0" />
  </joint>

  <gazebo reference="LFsrRL_joint">
    <implicitSpringDamper>1</implicitSpringDamper>
  </gazebo>

  <link name="RFootBumperRight_frame"/>
  <joint name="RFootBumperRight_joint" type="fixed">
    <parent link="r_ankle"/>
    <child link="RFootBumperRight_frame"/>
    <origin rpy="0 0 0" xyz="0.0876 -0.019 -0.035"/>
    <dynamics damping="0.1" friction="0" />
  </joint>

  <gazebo reference="RFootBumperRight_joint">
    <implicitSpringDamper>1</implicitSpringDamper>
  </gazebo>

  <link name="LHandTouchLeft_frame"/>
  <joint name="LHandTouchLeft_joint" type="fixed">
    <parent link="l_wrist"/>
    <child link="LHandTouchLeft_frame"/>
    <origin rpy="0 0 0" xyz="0.032 0.025 0.003"/>
    <dynamics damping="0.1" friction="0" />
  </joint>

  <gazebo reference="LHandTouchLeft_joint">
    <implicitSpringDamper>1</implicitSpringDamper>
  </gazebo>

  <link name="RInfraRed_frame"/>
  <joint name="RInfraRed_joint" type="fixed">
    <parent link="Head"/>
    <child link="RInfraRed_frame"/>
    <origin rpy="0 0 0" xyz="0.0441 -0.0257 0.0466"/>
    <dynamics damping="0.1" friction="0" />
  </joint>

  <gazebo reference="RInfraRed_joint">
    <implicitSpringDamper>1</implicitSpringDamper>
  </gazebo>

  <link name="LFootBumperLeft_frame"/>
  <joint name="LFootBumperLeft_joint" type="fixed">
    <parent link="l_ankle"/>
    <child link="LFootBumperLeft_frame"/>
    <origin rpy="0 0 0" xyz="0.0876 0.019 -0.035"/>
    <dynamics damping="0.1" friction="0" />
  </joint>

  <gazebo reference="LFootBumperLeft_joint">
    <implicitSpringDamper>1</implicitSpringDamper>
  </gazebo>

  <link name="ChestButton_frame"/>
  <joint name="ChestButton_joint" type="fixed">
    <parent link="torso"/>
    <child link="ChestButton_frame"/>
    <origin rpy="0 0 0" xyz="0.049871 0.001588 0.055163"/>
    <dynamics damping="0.1" friction="0" />
  </joint>

  <gazebo reference="ChestButton_joint">
    <implicitSpringDamper>1</implicitSpringDamper>
  </gazebo>

  <link name="RFootBumperLeft_frame"/>
  <joint name="RFootBumperLeft_joint" type="fixed">
    <parent link="r_ankle"/>
    <child link="RFootBumperLeft_frame"/>
    <origin rpy="0 0 0" xyz="0.0876 0.014 -0.035"/>
    <dynamics damping="0.1" friction="0" />
  </joint>

  <gazebo reference="RFootBumperLeft_joint">
    <implicitSpringDamper>1</implicitSpringDamper>
  </gazebo>

  <link name="LFsrRR_frame"/>
  <joint name="LFsrRR_joint" type="fixed">
    <parent link="l_ankle"/>
    <child link="LFsrRR_frame"/>
    <origin rpy="0 0 0" xyz="-0.02965 -0.0191 0"/>
    <dynamics damping="0.1" friction="0" />
  </joint>

  <gazebo reference="LFsrRR_joint">
    <implicitSpringDamper>1</implicitSpringDamper>
  </gazebo>

  <link name="LFootBumperRight_frame"/>
  <joint name="LFootBumperRight_joint" type="fixed">
    <parent link="l_ankle"/>
    <child link="LFootBumperRight_frame"/>
    <origin rpy="0 0 0" xyz="0.0876 -0.014 -0.035"/>
    <dynamics damping="0.1" friction="0" />
  </joint>

  <gazebo reference="LFootBumperRight_joint">
    <implicitSpringDamper>1</implicitSpringDamper>
  </gazebo>

  <link name="RFsrFR_frame"/>
  <joint name="RFsrFR_joint" type="fixed">
    <parent link="r_ankle"/>
    <child link="RFsrFR_frame"/>
    <origin rpy="0 0 0" xyz="0.07025 -0.0299 0"/>
    <dynamics damping="0.1" friction="0" />
  </joint>

  <gazebo reference="RFsrFR_joint">
    <implicitSpringDamper>1</implicitSpringDamper>
  </gazebo>

  <link name="RHandTouchLeft_frame"/>
  <joint name="RHandTouchLeft_joint" type="fixed">
    <parent link="r_wrist"/>
    <child link="RHandTouchLeft_frame"/>
    <origin rpy="0 0 0" xyz="0.032 0.025 0.003"/>
    <dynamics damping="0.1" friction="0" />
  </joint>

  <gazebo reference="RHandTouchLeft_joint">
    <implicitSpringDamper>1</implicitSpringDamper>
  </gazebo>

  <link name="RFsrRR_frame"/>
  <joint name="RFsrRR_joint" type="fixed">
    <parent link="r_ankle"/>
    <child link="RFsrRR_frame"/>
    <origin rpy="0 0 0" xyz="-0.02965 -0.0299 0"/>
    <dynamics damping="0.1" friction="0" />
  </joint>

  <gazebo reference="RFsrRR_joint">
    <implicitSpringDamper>1</implicitSpringDamper>
  </gazebo>

  <link name="LFsrFL_frame"/>
  <joint name="LFsrFL_joint" type="fixed">
    <parent link="l_ankle"/>
    <child link="LFsrFL_frame"/>
    <origin rpy="0 0 0" xyz="0.07025 0.0299 0"/>
    <dynamics damping="0.1" friction="0" />
  </joint>

  <gazebo reference="LFsrFL_joint">
    <implicitSpringDamper>1</implicitSpringDamper>
  </gazebo>

  <link name="HeadTouchFront_frame"/>
  <joint name="HeadTouchFront_joint" type="fixed">
    <parent link="Head"/>
    <child link="HeadTouchFront_frame"/>
    <origin rpy="0 -1.186099535 0" xyz="0.0312 0 0.1014"/>
    <dynamics damping="0.1" friction="0" />
  </joint>

  <gazebo reference="HeadTouchFront_joint">
    <implicitSpringDamper>1</implicitSpringDamper>
  </gazebo>

  <link name="CameraBottom_frame"/>
  <joint name="CameraBottom_joint" type="fixed">
    <parent link="Head"/>
    <child link="CameraBottom_frame"/>
    <origin rpy="0 0.6929 0" xyz="0.05071 0 0.01774"/>
    <dynamics damping="0.1" friction="0" />
  </joint>

  <gazebo reference="CameraBottom_joint">
    <implicitSpringDamper>1</implicitSpringDamper>
  </gazebo>

  <link name="LHandTouchRight_frame"/>
  <joint name="LHandTouchRight_joint" type="fixed">
    <parent link="l_wrist"/>
    <child link="LHandTouchRight_frame"/>
    <origin rpy="0 0 0" xyz="0.035 -0.025 0.0035"/>
    <dynamics damping="0.1" friction="0" />
  </joint>

  <gazebo reference="LHandTouchRight_joint">
    <implicitSpringDamper>1</implicitSpringDamper>
  </gazebo>

  <link name="RSonar_frame"/>
  <joint name="RSonar_joint" type="fixed">
    <parent link="torso"/>
    <child link="RSonar_frame"/>
    <origin rpy="0 0.04365 -0.39265" xyz="0.0507 -0.03785 0.06035"/>
    <dynamics damping="0.1" friction="0" />
  </joint>

  <gazebo reference="RSonar_joint">
    <implicitSpringDamper>1</implicitSpringDamper>
  </gazebo>

  <link name="CameraTop_frame"/>
  <joint name="CameraTop_joint" type="fixed">
    <parent link="Head"/>
    <child link="CameraTop_frame"/>
    <origin rpy="0 0.0209 0" xyz="0.05871 0 0.06364"/>
    <dynamics damping="0.1" friction="0" />
  </joint>

  <gazebo reference="CameraTop_joint">
    <implicitSpringDamper>1</implicitSpringDamper>
  </gazebo>

  <link name="LHandTouchBack_frame"/>
  <joint name="LHandTouchBack_joint" type="fixed">
    <parent link="l_wrist"/>
    <child link="LHandTouchBack_frame"/>
    <origin rpy="0 -1.57079632679 0" xyz="0.038 0 0.025"/>
    <dynamics damping="0.1" friction="0" />
  </joint>

  <gazebo reference="LHandTouchBack_joint">
    <implicitSpringDamper>1</implicitSpringDamper>
  </gazebo>

  <link name="LInfraRed_frame"/>
  <joint name="LInfraRed_joint" type="fixed">
    <parent link="Head"/>
    <child link="LInfraRed_frame"/>
    <origin rpy="0 0 0" xyz="0.0441 0.0257 0.0466"/>
    <dynamics damping="0.1" friction="0" />
  </joint>

  <gazebo reference="LInfraRed_joint">
    <implicitSpringDamper>1</implicitSpringDamper>
  </gazebo>

  <link name="RHandTouchRight_frame"/>
  <joint name="RHandTouchRight_joint" type="fixed">
    <parent link="r_wrist"/>
    <child link="RHandTouchRight_frame"/>
    <origin rpy="0 0 0" xyz="0.035 -0.025 0.0035"/>
    <dynamics damping="0.1" friction="0" />
  </joint>

  <gazebo reference="RHandTouchRight_joint">
    <implicitSpringDamper>1</implicitSpringDamper>
  </gazebo>

</robot>

